Workbook
Name _10_noninc.log: 'int - 4k'!#REF!
Name _10_noninc.log_1: 'int - 2k'!#REF!
Name _10p.log: 'int - 10k'!$B$3:$C$71
Name _10p.log: 'int - 10p'!$B$3:$C$71
Name _10p.log: 'int - 2k'!$B$3:$C$71
Name _10p.log: 'int - 4k'!$B$2:$C$71
Name _10p.log: 'int - 6k'!$B$3:$C$71
Name _10p.log: 'int - 8k'!$B$3:$C$71
Name _10p.log: 'int - empty'!$B$3:$C$71
Name _10p.log: 'str - 10k'!$B$3:$C$71
Name _10p.log: 'str - 10p'!$B$3:$C$71
Name _10p.log: 'str - 2k'!$B$3:$C$71
Name _10p.log: 'str - 4k'!$B$3:$C$71
Name _10p.log: 'str - 6k'!$B$3:$C$71
Name _10p.log: 'str - 8k'!$B$3:$C$71
Name _10p.log_1: 'int - 10k'!#REF!
Name _10p.log_1: 'int - 4k'!#REF!
Name _10p.log_1: 'int - 6k'!#REF!
Name _10p.log_1: 'str - 10k'!#REF!
Name _10p.log_1: 'str - 4k'!#REF!
Name _10p.log_1: 'str - 6k'!#REF!
Name _10p.log_1: 'str - 8k'!#REF!
Name _10p.log_2: 'str - 10k'!#REF!
Name _10p.log_2: 'str - 6k'!#REF!
Name _10p.log_2: 'str - 8k'!#REF!
Name _12p.log: 'int - 10k'!#REF!
Name _12p.log: 'int - 6k'!#REF!
Name _12p.log: 'str - 6k'!#REF!
Name _12p.log: 'str - 8k'!#REF!
Name _14p.log: 'int - 10k'!#REF!
Name _14p.log: 'int - 6k'!#REF!
Name _14p.log: 'str - 6k'!#REF!
Name _15_noninc.log: 'int - 4k'!#REF!
Name _15p.log: 'int - 4k'!#REF!
Name _15p.log: 'str - 10k'!#REF!
Name _15p.log: 'str - 4k'!#REF!
Name _15p.log: 'str - 6k'!#REF!
Name _15p.log: 'str - 8k'!#REF!
Name _16p.log: 'int - 6k'!#REF!
Name _16p.log: 'str - 6k'!#REF!
Name _18p.log: 'int - 6k'!#REF!
Name _20_noninc.log: 'int - 2k'!#REF!
Name _20_noninc.log: 'int - 4k'!#REF!
Name _20_noninc.log_1: 'int - 2k'!#REF!
Name _20p.log: 'int - 10k'!$C$3:$C$68
Name _20p.log: 'int - 10p'!$C$3:$C$68
Name _20p.log: 'int - 2k'!$C$3:$C$68
Name _20p.log: 'int - 4k'!$C$2:$C$68
Name _20p.log: 'int - 6k'!$C$3:$C$68
Name _20p.log: 'int - 8k'!$C$3:$C$68
Name _20p.log: 'int - empty'!$C$3:$C$68
Name _20p.log: 'str - 10k'!$C$3:$C$68
Name _20p.log: 'str - 10p'!$C$3:$C$68
Name _20p.log: 'str - 2k'!$C$3:$C$68
Name _20p.log: 'str - 4k'!$C$3:$C$68
Name _20p.log: 'str - 6k'!$C$3:$C$68
Name _20p.log: 'str - 8k'!$C$3:$C$68
Name _20p.log_1: 'int - 4k'!#REF!
Name _20p.log_1: 'int - 6k'!#REF!
Name _20p.log_1: 'str - 10k'!#REF!

Sheet int - 2k
A1: scalabilityInt - tuples/peer: | B1: 2k
A2: #peers | B2: 10 | C2: 20 | D2: 30 | E2: 40 | F2: 50 | G2: 60 | H2: 70
A3: initial solution
A4: RUN 1 | B4: 8049 | C4: 27971 | D4: 46769 | E4: 87196 | F4: 89045 | G4: 117578 | H4: 117687
A5: RUN 2 | B5: 5959 | C5: 24445 | D5: 40810 | E5: 70983 | F5: 92041 | G5: 130292 | H5: 122351
A6: RUN 3 | B6: 5928 | C6: 24133 | D6: 40592 | E6: 70250 | F6: 79171 | G6: 123678 | H6: 107781
A7: RUN 4 | B7: 5959 | C7: 24195 | D7: 40607 | E7: 70435 | F7: 77923 | G7: 130588 | H7: 105316
A8: RUN 5 | B8: 5975 | C8: 24523 | D8: 41028 | E8: 70576 | F8: 77299 | G8: 117578 | H8: 103116
A9: AVG | B9: =(SUM(B4:B8) -MAX(B4:B8) -MIN(B4:B8))/((COUNT(B4:B8)-2)*1000) -> 5.9643333 | C9: =(SUM(C4:C8) -MAX(C4:C8) -MIN(C4:C8))/((COUNT(C4:C8)-2)*1000) -> 24.387667 | D9: =(SUM(D4:D8) -MAX(D4:D8) -MIN(D4:D8))/((COUNT(D4:D8)-2)*1000) -> 40.815 | E9: =(SUM(E4:E8) -MAX(E4:E8) -MIN(E4:E8))/((COUNT(E4:E8)-2)*1000) -> 70.664667 | F9: =(SUM(F4:F8) -MAX(F4:F8) -MIN(F4:F8))/((COUNT(F4:F8)-2)*1000) -> 82.046333 | G9: =(SUM(G4:G8) -MAX(G4:G8) -MIN(G4:G8))/((COUNT(G4:G8)-2)*1000) -> 123.84933 | H9: =(SUM(H4:H8) -MAX(H4:H8) -MIN(H4:H8))/((COUNT(H4:H8)-2)*1000) -> 110.26133 | I9: sec
A10: STDEV | B10: =STDEV(B4:B8)/1000 -> 0.93650841 | C10: =STDEV(C4:C8)/1000 -> 1.6391958 | D10: =STDEV(D4:D8)/1000 -> 2.6934936 | E10: =STDEV(E4:E8)/1000 -> 7.4442845 | F10: =STDEV(F4:F8)/1000 -> 6.9132913 | G10: =STDEV(G4:G8)/1000 -> 6.4335546 | H10: =STDEV(H4:H8)/1000 -> 8.3377971
A11: CONFIDENCE | B11: =CONFIDENCE(0.05,B10,5) -> 0.82087073 | C11: =CONFIDENCE(0.05,C10,5) -> 1.436792 | D11: =CONFIDENCE(0.05,D10,5) -> 2.3609078 | E11: =CONFIDENCE(0.05,E10,5) -> 6.5250831 | F11: =CONFIDENCE(0.05,F10,5) -> 6.0596557 | G11: =CONFIDENCE(0.05,G10,5) -> 5.6391557 | H11: =CONFIDENCE(0.05,H10,5) -> 7.3082671
A13: incremental deletions 1%
A14: RUN 1 | B14: 7691 | C14: 16411 | D14: 27581 | E14: 39936 | F14: 45708 | G14: 59545 | H14: 62806
A15: RUN 2 | B15: 858 | C15: 1576 | D15: 3869 | E15: 4649 | F15: 6708 | G15: 10827 | H15: 8658
A16: RUN 3 | B16: 874 | C16: 1498 | D16: 3479 | E16: 4789 | F16: 6661 | G16: 12979 | H16: 8690
A17: RUN 4 | B17: 843 | C17: 1544 | D17: 3573 | E17: 4836 | F17: 6661 | G17: 10655 | H17: 10078
A18: RUN 5 | B18: 858 | C18: 1560 | D18: 3323 | E18: 4914 | F18: 6677 | G18: 11325 | H18: 10577
A19: AVG | B19: =(SUM(B14:B18) -MAX(B14:B18) -MIN(B14:B18))/((COUNT(B14:B18)-2)*1000) -> 0.86333333 | C19: =(SUM(C14:C18) -MAX(C14:C18) -MIN(C14:C18))/((COUNT(C14:C18)-2)*1000) -> 1.56 | D19: =(SUM(D14:D18) -MAX(D14:D18) -MIN(D14:D18))/((COUNT(D14:D18)-2)*1000) -> 3.6403333 | E19: =(SUM(E14:E18) -MAX(E14:E18) -MIN(E14:E18))/((COUNT(E14:E18)-2)*1000) -> 4.8463333 | F19: =(SUM(F14:F18) -MAX(F14:F18) -MIN(F14:F18))/((COUNT(F14:F18)-2)*1000) -> 6.682 | G19: =(SUM(G14:G18) -MAX(G14:G18) -MIN(G14:G18))/((COUNT(G14:G18)-2)*1000) -> 11.710333 | H19: =(SUM(H14:H18) -MAX(H14:H18) -MIN(H14:H18))/((COUNT(H14:H18)-2)*1000) -> 9.7816667 | I19: sec
A20: STDEV | B20: =STDEV(B14:B18)/1000 -> 3.0557184 | C20: =STDEV(C14:C18)/1000 -> 6.6485647 | D20: =STDEV(D14:D18)/1000 -> 10.743913 | E20: =STDEV(E14:E18)/1000 -> 15.714934 | F20: =STDEV(F14:F18)/1000 -> 17.455316 | G20: =STDEV(G14:G18)/1000 -> 21.529899 | H20: =STDEV(H14:H18)/1000 -> 23.853819
A21: CONFIDENCE | B21: =CONFIDENCE(0.05,B20,5) -> 2.678406 | C21: =CONFIDENCE(0.05,C20,5) -> 5.8276169 | D21: =CONFIDENCE(0.05,D20,5) -> 9.4172822 | E21: =CONFIDENCE(0.05,E20,5) -> 13.774494 | F21: =CONFIDENCE(0.05,F20,5) -> 15.299978 | G21: =CONFIDENCE(0.05,G20,5) -> 18.871441 | H21: =CONFIDENCE(0.05,H20,5) -> 20.90841
A23: incremental deletions 10%
A24: RUN 1 | B24: 1202 | C24: 2184 | D24: 4477 | E24: 6365 | F24: 9142 | G24: 13759 | H24: 14976
A25: RUN 2 | B25: 1155 | C25: 1997 | D25: 4149 | E25: 5897 | F25: 8767 | G25: 13572 | H25: 13494
A26: RUN 3 | B26: 1155 | C26: 1904 | D26: 4352 | E26: 5366 | F26: 8097 | G26: 13431 | H26: 14540
A27: RUN 4 | B27: 1154 | C27: 1778 | D27: 3822 | E27: 5991 | F27: 8190 | G27: 13244 | H27: 14118
A28: RUN 5 | B28: 1139 | C28: 1794 | D28: 4883 | E28: 5210 | F28: 8003 | G28: 13775 | H28: 11638
A29: AVG | B29: =(SUM(B24:B28) -MAX(B24:B28) -MIN(B24:B28))/((COUNT(B24:B28)-2)*1000) -> 1.1546667 | C29: =(SUM(C24:C28) -MAX(C24:C28) -MIN(C24:C28))/((COUNT(C24:C28)-2)*1000) -> 1.8983333 | D29: =(SUM(D24:D28) -MAX(D24:D28) -MIN(D24:D28))/((COUNT(D24:D28)-2)*1000) -> 4.326 | E29: =(SUM(E24:E28) -MAX(E24:E28) -MIN(E24:E28))/((COUNT(E24:E28)-2)*1000) -> 5.7513333 | F29: =(SUM(F24:F28) -MAX(F24:F28) -MIN(F24:F28))/((COUNT(F24:F28)-2)*1000) -> 8.3513333 | G29: =(SUM(G24:G28) -MAX(G24:G28) -MIN(G24:G28))/((COUNT(G24:G28)-2)*1000) -> 13.587333 | H29: =(SUM(H24:H28) -MAX(H24:H28) -MIN(H24:H28))/((COUNT(H24:H28)-2)*1000) -> 14.050667 | I29: sec
A30: STDEV | B30: =STDEV(B24:B28)/1000 -> 0.023906066 | C30: =STDEV(C24:C28)/1000 -> 0.16678669 | D30: =STDEV(D24:D28)/1000 -> 0.39322678 | E30: =STDEV(E24:E28)/1000 -> 0.47321317 | F30: =STDEV(F24:F28)/1000 -> 0.49265881 | G30: =STDEV(G24:G28)/1000 -> 0.22494155 | H30: =STDEV(H24:H28)/1000 -> 1.3027499
A31: CONFIDENCE | B31: =CONFIDENCE(0.05,B30,5) -> 0.020954206 | C31: =CONFIDENCE(0.05,C30,5) -> 0.14619229 | D31: =CONFIDENCE(0.05,D30,5) -> 0.34467214 | E31: =CONFIDENCE(0.05,E30,5) -> 0.41478201 | F31: =CONFIDENCE(0.05,F30,5) -> 0.43182655 | G31: =CONFIDENCE(0.05,G30,5) -> 0.19716634 | H31: =CONFIDENCE(0.05,H30,5) -> 1.1418896
A33: incremental deletions 50%
A34: RUN 1 | B34: 2278 | C34: 2808 | D34: 5257 | E34: 8378 | F34: 15038 | G34: 20592 | H34: 17207
A35: RUN 2 | B35: 2402 | C35: 2917 | D35: 5367 | E35: 13354 | F35: 16333 | G35: 26770 | H35: 20343
A36: RUN 3 | B36: 2403 | C36: 2886 | D36: 5491 | E36: 12012 | F36: 16863 | G36: 25226 | H36: 17846
A37: RUN 4 | B37: 2402 | C37: 2886 | D37: 5522 | E37: 13010 | F37: 16832 | G37: 23853 | H37: 19017
A38: RUN 5 | B38: 2387 | C38: 3026 | D38: 5476 | E38: 11607 | F38: 18253 | G38: 25599 | H38: 20499
A39: AVG | B39: =(SUM(B34:B38) -MAX(B34:B38) -MIN(B34:B38))/((COUNT(B34:B38)-2)*1000) -> 2.397 | C39: =(SUM(C34:C38) -MAX(C34:C38) -MIN(C34:C38))/((COUNT(C34:C38)-2)*1000) -> 2.8963333 | D39: =(SUM(D34:D38) -MAX(D34:D38) -MIN(D34:D38))/((COUNT(D34:D38)-2)*1000) -> 5.4446667 | E39: =(SUM(E34:E38) -MAX(E34:E38) -MIN(E34:E38))/((COUNT(E34:E38)-2)*1000) -> 12.209667 | F39: =(SUM(F34:F38) -MAX(F34:F38) -MIN(F34:F38))/((COUNT(F34:F38)-2)*1000) -> 16.676 | G39: =(SUM(G34:G38) -MAX(G34:G38) -MIN(G34:G38))/((COUNT(G34:G38)-2)*1000) -> 24.892667 | H39: =(SUM(H34:H38) -MAX(H34:H38) -MIN(H34:H38))/((COUNT(H34:H38)-2)*1000) -> 19.068667 | I39: sec
A40: STDEV | B40: =STDEV(B34:B38)/1000 -> 0.05429825 | C40: =STDEV(C34:C38)/1000 -> 0.078922747 | D40: =STDEV(D34:D38)/1000 -> 0.10945912 | E40: =STDEV(E34:E38)/1000 -> 1.9741852 | F40: =STDEV(F34:F38)/1000 -> 1.1560907 | G40: =STDEV(G34:G38)/1000 -> 2.3736328 | H40: =STDEV(H34:H38)/1000 -> 1.465943
A41: CONFIDENCE | B41: =CONFIDENCE(0.05,B40,5) -> 0.04759364 | C41: =CONFIDENCE(0.05,C40,5) -> 0.069177567 | D41: =CONFIDENCE(0.05,D40,5) -> 0.09594339 | E41: =CONFIDENCE(0.05,E40,5) -> 1.7304178 | F41: =CONFIDENCE(0.05,F40,5) -> 1.0133396 | G41: =CONFIDENCE(0.05,G40,5) -> 2.0805426 | H41: =CONFIDENCE(0.05,H40,5) -> 1.2849321
A43: incremental insertions 1%
A44: RUN 1 | B44: 1217 | C44: 6271 | D44: 8830 | E44: 23806 | F44: 24040 | G44: 32760 | H44: 32464
...

Sheet int - 4k
A1: scalabilityInt - tuples/peer: | B1: 4k
A2: #peers | B2: 5 | C2: 10 | D2: 15 | E2: 20 | F2: 25 | G2: 30 | H2: 35
A3: initial solution
A4: RUN 1 | B4: 4758 | C4: 12963 | D4: 33680 | E4: 51282 | F4: 42853 | G4: 88874 | H4: 75738
A5: RUN 2 | B5: 4087 | C5: 11732 | D5: 33165 | E5: 51405 | F5: 40170 | G5: 88952 | H5: 78234
A6: RUN 3 | B6: 4072 | C6: 11731 | D6: 33228 | E6: 50608 | F6: 39921 | G6: 86627 | H6: 78391
A7: RUN 4 | B7: 4072 | C7: 11779 | D7: 33135 | E7: 52761 | F7: 39858 | G7: 83508 | H7: 76191
A8: RUN 5 | B8: 4087 | C8: 11762 | D8: 32822 | E8: 89857 | F8: 39843 | G8: 84443 | H8: 83617
A9: AVG | B9: =(SUM(B4:B8) -MAX(B4:B8) -MIN(B4:B8))/((COUNT(B4:B8)-2)*1000) -> 4.082 | C9: =(SUM(C4:C8) -MAX(C4:C8) -MIN(C4:C8))/((COUNT(C4:C8)-2)*1000) -> 11.757667 | D9: =(SUM(D4:D8) -MAX(D4:D8) -MIN(D4:D8))/((COUNT(D4:D8)-2)*1000) -> 33.176 | E9: =(SUM(E4:E8) -MAX(E4:E8) -MIN(E4:E8))/((COUNT(E4:E8)-2)*1000) -> 51.816 | F9: =(SUM(F4:F8) -MAX(F4:F8) -MIN(F4:F8))/((COUNT(F4:F8)-2)*1000) -> 39.983 | G9: =(SUM(G4:G8) -MAX(G4:G8) -MIN(G4:G8))/((COUNT(G4:G8)-2)*1000) -> 86.648 | H9: =(SUM(H4:H8) -MAX(H4:H8) -MIN(H4:H8))/((COUNT(H4:H8)-2)*1000) -> 77.605333 | I9: sec
A10: STDEV | B10: =STDEV(B4:B8)/1000 -> 0.3035271 | C10: =STDEV(C4:C8)/1000 -> 0.54240695 | D10: =STDEV(D4:D8)/1000 -> 0.30795211 | E10: =STDEV(E4:E8)/1000 -> 17.1653 | F10: =STDEV(F4:F8)/1000 -> 1.3057908 | G10: =STDEV(G4:G8)/1000 -> 2.492277 | H10: =STDEV(H4:H8)/1000 -> 3.1306869
A11: CONFIDENCE | B11: =CONFIDENCE(0.05,B10,5) -> 0.26604834 | C11: =CONFIDENCE(0.05,C10,5) -> 0.47543192 | D11: =CONFIDENCE(0.05,D10,5) -> 0.26992696 | E11: =CONFIDENCE(0.05,E10,5) -> 15.045772 | F11: =CONFIDENCE(0.05,F10,5) -> 1.144555 | G11: =CONFIDENCE(0.05,G10,5) -> 2.184537 | H11: =CONFIDENCE(0.05,H10,5) -> 2.7441177
A13: incremental deletions 1%
A14: RUN 1 | B14: 2840 | C14: 7395 | D14: 13463 | E14: 19298 | F14: 22526 | G14: 27191 | H14: 31996
A15: RUN 2 | B15: 312 | C15: 1030 | D15: 1529 | E15: 2824 | F15: 3198 | G15: 3838 | H15: 3869
A16: RUN 3 | B16: 297 | C16: 1076 | D16: 1529 | E16: 2387 | F16: 3151 | G16: 3744 | H16: 3806
A17: RUN 4 | B17: 312 | C17: 1092 | D17: 1544 | E17: 2308 | F17: 3198 | G17: 3744 | H17: 3838
A18: RUN 5 | B18: 312 | C18: 1076 | D18: 1513 | E18: 2231 | F18: 3151 | G18: 3760 | H18: 3853
A19: AVG | B19: =(SUM(B14:B18) -MAX(B14:B18) -MIN(B14:B18))/((COUNT(B14:B18)-2)*1000) -> 0.312 | C19: =(SUM(C14:C18) -MAX(C14:C18) -MIN(C14:C18))/((COUNT(C14:C18)-2)*1000) -> 1.0813333 | D19: =(SUM(D14:D18) -MAX(D14:D18) -MIN(D14:D18))/((COUNT(D14:D18)-2)*1000) -> 1.534 | E19: =(SUM(E14:E18) -MAX(E14:E18) -MIN(E14:E18))/((COUNT(E14:E18)-2)*1000) -> 2.5063333 | F19: =(SUM(F14:F18) -MAX(F14:F18) -MIN(F14:F18))/((COUNT(F14:F18)-2)*1000) -> 3.1823333 | G19: =(SUM(G14:G18) -MAX(G14:G18) -MIN(G14:G18))/((COUNT(G14:G18)-2)*1000) -> 3.7806667 | H19: =(SUM(H14:H18) -MAX(H14:H18) -MIN(H14:H18))/((COUNT(H14:H18)-2)*1000) -> 3.8533333 | I19: sec
A20: STDEV | B20: =STDEV(B14:B18)/1000 -> 1.1322517 | C20: =STDEV(C14:C18)/1000 -> 2.8293917 | D20: =STDEV(D14:D18)/1000 -> 5.3371701 | E20: =STDEV(E14:E18)/1000 -> 7.5437476 | F20: =STDEV(F14:F18)/1000 -> 8.6542858 | G20: =STDEV(G14:G18)/1000 -> 10.473591 | H20: =STDEV(H14:H18)/1000 -> 12.591097
A21: CONFIDENCE | B21: =CONFIDENCE(0.05,B20,5) -> 0.99244409 | C21: =CONFIDENCE(0.05,C20,5) -> 2.4800256 | D21: =CONFIDENCE(0.05,D20,5) -> 4.6781499 | E21: =CONFIDENCE(0.05,E20,5) -> 6.6122648 | F21: =CONFIDENCE(0.05,F20,5) -> 7.5856766 | G21: =CONFIDENCE(0.05,G20,5) -> 9.1803388 | H21: =CONFIDENCE(0.05,H20,5) -> 11.03638
A23: incremental deletions 10%
A24: RUN 1 | B24: 344 | C24: 1607 | D24: 2028 | E24: 3073 | F24: 4197 | G24: 4867 | H24: 4524
A25: RUN 2 | B25: 359 | C25: 1685 | D25: 2106 | E25: 3338 | F25: 4493 | G25: 4945 | H25: 4914
A26: RUN 3 | B26: 359 | C26: 1716 | D26: 2059 | E26: 2979 | F26: 4213 | G26: 4618 | H26: 4368
A27: RUN 4 | B27: 358 | C27: 1669 | D27: 2059 | E27: 2683 | F27: 4212 | G27: 4648 | H27: 4383
A28: RUN 5 | B28: 344 | C28: 1685 | D28: 2106 | E28: 2699 | F28: 4243 | G28: 4478 | H28: 4446
A29: AVG | B29: =(SUM(B24:B28) -MAX(B24:B28) -MIN(B24:B28))/((COUNT(B24:B28)-2)*1000) -> 0.35366667 | C29: =(SUM(C24:C28) -MAX(C24:C28) -MIN(C24:C28))/((COUNT(C24:C28)-2)*1000) -> 1.6796667 | D29: =(SUM(D24:D28) -MAX(D24:D28) -MIN(D24:D28))/((COUNT(D24:D28)-2)*1000) -> 2.0746667 | E29: =(SUM(E24:E28) -MAX(E24:E28) -MIN(E24:E28))/((COUNT(E24:E28)-2)*1000) -> 2.917 | F29: =(SUM(F24:F28) -MAX(F24:F28) -MIN(F24:F28))/((COUNT(F24:F28)-2)*1000) -> 4.2226667 | G29: =(SUM(G24:G28) -MAX(G24:G28) -MIN(G24:G28))/((COUNT(G24:G28)-2)*1000) -> 4.711 | H29: =(SUM(H24:H28) -MAX(H24:H28) -MIN(H24:H28))/((COUNT(H24:H28)-2)*1000) -> 4.451 | I29: sec
A30: STDEV | B30: =STDEV(B24:B28)/1000 -> 0.008043631 | C30: =STDEV(C24:C28)/1000 -> 0.040333609 | D30: =STDEV(D24:D28)/1000 -> 0.033857052 | E30: =STDEV(E24:E28)/1000 -> 0.27418388 | F30: =STDEV(F24:F28)/1000 -> 0.12488715 | G30: =STDEV(G24:G28)/1000 -> 0.19104895 | H30: =STDEV(H24:H28)/1000 -> 0.22491999
A31: CONFIDENCE | B31: =CONFIDENCE(0.05,B30,5) -> 0.0070504239 | C31: =CONFIDENCE(0.05,C30,5) -> 0.035353317 | D31: =CONFIDENCE(0.05,D30,5) -> 0.02967647 | E31: =CONFIDENCE(0.05,E30,5) -> 0.24032835 | F31: =CONFIDENCE(0.05,F30,5) -> 0.1094664 | G31: =CONFIDENCE(0.05,G30,5) -> 0.16745871 | H31: =CONFIDENCE(0.05,H30,5) -> 0.19714744
A33: incremental deletions 50%
A34: RUN 1 | B34: 546 | C34: 4087 | D34: 3884 | E34: 4883 | F34: 7925 | G34: 8736 | H34: 9547
A35: RUN 2 | B35: 592 | C35: 4321 | D35: 4157 | E35: 4946 | F35: 8315 | G35: 10624 | H35: 11263
A36: RUN 3 | B36: 593 | C36: 4321 | D36: 4142 | E36: 4992 | F36: 8331 | G36: 10608 | H36: 12573
A37: RUN 4 | B37: 577 | C37: 4322 | D37: 4125 | E37: 4961 | F37: 8361 | G37: 11045 | H37: 11388
A38: RUN 5 | B38: 593 | C38: 4306 | D38: 4142 | E38: 4977 | F38: 8393 | G38: 10593 | H38: 9313
A39: AVG | B39: =(SUM(B34:B38) -MAX(B34:B38) -MIN(B34:B38))/((COUNT(B34:B38)-2)*1000) -> 0.58733333 | C39: =(SUM(C34:C38) -MAX(C34:C38) -MIN(C34:C38))/((COUNT(C34:C38)-2)*1000) -> 4.316 | D39: =(SUM(D34:D38) -MAX(D34:D38) -MIN(D34:D38))/((COUNT(D34:D38)-2)*1000) -> 4.1363333 | E39: =(SUM(E34:E38) -MAX(E34:E38) -MIN(E34:E38))/((COUNT(E34:E38)-2)*1000) -> 4.9613333 | F39: =(SUM(F34:F38) -MAX(F34:F38) -MIN(F34:F38))/((COUNT(F34:F38)-2)*1000) -> 8.3356667 | G39: =(SUM(G34:G38) -MAX(G34:G38) -MIN(G34:G38))/((COUNT(G34:G38)-2)*1000) -> 10.608333 | H39: =(SUM(H34:H38) -MAX(H34:H38) -MIN(H34:H38))/((COUNT(H34:H38)-2)*1000) -> 10.732667 | I39: sec
A40: STDEV | B40: =STDEV(B34:B38)/1000 -> 0.020290392 | C40: =STDEV(C34:C38)/1000 -> 0.10329714 | D40: =STDEV(D34:D38)/1000 -> 0.11571301 | E40: =STDEV(E34:E38)/1000 -> 0.042139056 | F40: =STDEV(F34:F38)/1000 -> 0.19239023 | G40: =STDEV(G34:G38)/1000 -> 0.90616814 | H40: =STDEV(H34:H38)/1000 -> 1.367791
A41: CONFIDENCE | B41: =CONFIDENCE(0.05,B40,5) -> 0.017784986 | C41: =CONFIDENCE(0.05,C40,5) -> 0.090542275 | D41: =CONFIDENCE(0.05,D40,5) -> 0.10142506 | E41: =CONFIDENCE(0.05,E40,5) -> 0.036935832 | F41: =CONFIDENCE(0.05,F40,5) -> 0.16863437 | G41: =CONFIDENCE(0.05,G40,5) -> 0.7942768 | H41: =CONFIDENCE(0.05,H40,5) -> 1.1988996
A43: incremental insertions 1%
A44: RUN 1 | B44: 780 | C44: 1809 | D44: 5798 | E44: 13229 | F44: 10437 | G44: 21497 | H44: 20139
...

Sheet int - 6k
A1: scalabilityInt - tuples/peer: | B1: 6k
A2: #peers | B2: 2 | C2: 4 | D2: 6 | E2: 8 | F2: 10 | G2: 12 | H2: 14 | I2: 16 | J2: 18 | K2: 20 | L2: 22
A3: initial solution
A4: RUN 1 | B4: 1498 | C4: 4820 | D4: 10593 | E4: 19220 | F4: 17441 | G4: 35818 | H4: 43259 | I4: 69810 | J4: 81698 | K4: 73165 | L4: 62541
A5: RUN 2 | B5: 1388 | C5: 4493 | D5: 10343 | E5: 20311 | F5: 17332 | G5: 43088 | H5: 44382 | I5: 78343 | J5: 94397 | K5: 76534 | L5: 63555
A6: RUN 3 | B6: 1373 | C6: 4493 | D6: 10233 | E6: 20998 | F6: 17269 | G6: 43244 | H6: 44492 | I6: 76783 | J6: 94958 | K6: 88626 | L6: 63508
A7: RUN 4 | B7: 1388 | C7: 4508 | D7: 10249 | E7: 19094 | F7: 17285 | G7: 42620 | H7: 44398 | I7: 76831 | J7: 92415 | K7: 88179 | L7: 63336
A8: RUN 5 | B8: 1389 | C8: 4508 | D8: 10296 | E8: 19079 | F8: 17300 | G8: 42417 | H8: 44476 | I8: 79201 | J8: 96253 | K8: 87760 | L8: 63384
A9: AVG | B9: =(SUM(B4:B8) -MAX(B4:B8) -MIN(B4:B8))/((COUNT(B4:B8)-2)*1000) -> 1.3883333 | C9: =(SUM(C4:C8) -MAX(C4:C8) -MIN(C4:C8))/((COUNT(C4:C8)-2)*1000) -> 4.503 | D9: =(SUM(D4:D8) -MAX(D4:D8) -MIN(D4:D8))/((COUNT(D4:D8)-2)*1000) -> 10.296 | E9: =(SUM(E4:E8) -MAX(E4:E8) -MIN(E4:E8))/((COUNT(E4:E8)-2)*1000) -> 19.541667 | F9: =(SUM(F4:F8) -MAX(F4:F8) -MIN(F4:F8))/((COUNT(F4:F8)-2)*1000) -> 17.305667 | G9: =(SUM(G4:G8) -MAX(G4:G8) -MIN(G4:G8))/((COUNT(G4:G8)-2)*1000) -> 42.708333 | H9: =(SUM(H4:H8) -MAX(H4:H8) -MIN(H4:H8))/((COUNT(H4:H8)-2)*1000) -> 44.418667 | I9: =(SUM(I4:I8) -MAX(I4:I8) -MIN(I4:I8))/((COUNT(I4:I8)-2)*1000) -> 77.319 | ... L9: =(SUM(L4:L8) -MAX(L4:L8) -MIN(L4:L8))/((COUNT(L4:L8)-2)*1000) -> 63.409333 | M9: sec
A10: STDEV | B10: =STDEV(B4:B8)/1000 -> 0.051192773 | C10: =STDEV(C4:C8)/1000 -> 0.14308145 | D10: =STDEV(D4:D8)/1000 -> 0.14632566 | E10: =STDEV(E4:E8)/1000 -> 0.87081014 | F10: =STDEV(F4:F8)/1000 -> 0.068675323 | G10: =STDEV(G4:G8)/1000 -> 3.159276 | H10: =STDEV(H4:H8)/1000 -> 0.52897051 | I10: =STDEV(I4:I8)/1000 -> 3.7137715 | ... L10: =STDEV(L4:L8)/1000 -> 0.41428456
A11: CONFIDENCE | B11: =CONFIDENCE(0.05,B10,5) -> 0.044871619 | C11: =CONFIDENCE(0.05,C10,5) -> 0.12541411 | D11: =CONFIDENCE(0.05,D10,5) -> 0.12825774 | E11: =CONFIDENCE(0.05,E10,5) -> 0.76328472 | F11: =CONFIDENCE(0.05,F10,5) -> 0.060195469 | G11: =CONFIDENCE(0.05,G10,5) -> 2.7691766 | H11: =CONFIDENCE(0.05,H10,5) -> 0.46365457 | I11: =CONFIDENCE(0.05,I10,5) -> 3.2552044 | ... L11: =CONFIDENCE(0.05,L10,5) -> 0.36312976
A13: incremental deletions 1%
A14: RUN 1 | B14: 639 | C14: 2199 | D14: 4228 | E14: 6255 | F14: 7754 | G14: 11497 | H14: 13338 | I14: 16130 | J14: 17285 | K14: 18366 | L14: 19188
A15: RUN 2 | B15: 109 | C15: 343 | D15: 577 | E15: 920 | F15: 1279 | G15: 1342 | H15: 1529 | I15: 2902 | J15: 2558 | K15: 2388 | L15: 1919
A16: RUN 3 | B16: 125 | C16: 343 | D16: 561 | E16: 858 | F16: 1279 | G16: 1310 | H16: 1513 | I16: 2590 | J16: 2558 | K16: 2340 | L16: 1934
A17: RUN 4 | B17: 124 | C17: 328 | D17: 561 | E17: 826 | F17: 1263 | G17: 1342 | H17: 1514 | I17: 2371 | J17: 2465 | K17: 2293 | L17: 1981
A18: RUN 5 | B18: 125 | C18: 344 | D18: 593 | E18: 826 | F18: 1310 | G18: 1341 | H18: 1482 | I18: 2199 | J18: 2465 | K18: 2371 | L18: 1919
A19: AVG | B19: =(SUM(B14:B18) -MAX(B14:B18) -MIN(B14:B18))/((COUNT(B14:B18)-2)*1000) -> 0.12466667 | C19: =(SUM(C14:C18) -MAX(C14:C18) -MIN(C14:C18))/((COUNT(C14:C18)-2)*1000) -> 0.34333333 | D19: =(SUM(D14:D18) -MAX(D14:D18) -MIN(D14:D18))/((COUNT(D14:D18)-2)*1000) -> 0.577 | E19: =(SUM(E14:E18) -MAX(E14:E18) -MIN(E14:E18))/((COUNT(E14:E18)-2)*1000) -> 0.868 | F19: =(SUM(F14:F18) -MAX(F14:F18) -MIN(F14:F18))/((COUNT(F14:F18)-2)*1000) -> 1.2893333 | G19: =(SUM(G14:G18) -MAX(G14:G18) -MIN(G14:G18))/((COUNT(G14:G18)-2)*1000) -> 1.3416667 | H19: =(SUM(H14:H18) -MAX(H14:H18) -MIN(H14:H18))/((COUNT(H14:H18)-2)*1000) -> 1.5186667 | I19: =(SUM(I14:I18) -MAX(I14:I18) -MIN(I14:I18))/((COUNT(I14:I18)-2)*1000) -> 2.621 | ... L19: =(SUM(L14:L18) -MAX(L14:L18) -MIN(L14:L18))/((COUNT(L14:L18)-2)*1000) -> 1.9446667 | M19: sec
A20: STDEV | B20: =STDEV(B14:B18)/1000 -> 0.23186807 | C20: =STDEV(C14:C18)/1000 -> 0.83162029 | D20: =STDEV(D14:D18)/1000 -> 1.6346195 | E20: =STDEV(E14:E18)/1000 -> 2.4141404 | F20: =STDEV(F14:F18)/1000 -> 2.8940811 | G20: =STDEV(G14:G18)/1000 -> 4.5451643 | H20: =STDEV(H14:H18)/1000 -> 5.2898936 | I20: =STDEV(I14:I18)/1000 -> 6.0942529 | ... L20: =STDEV(L14:L18)/1000 -> 7.7143646
A21: CONFIDENCE | B21: =CONFIDENCE(0.05,B20,5) -> 0.20323759 | C21: =CONFIDENCE(0.05,C20,5) -> 0.72893393 | D21: =CONFIDENCE(0.05,D20,5) -> 1.4327809 | E21: =CONFIDENCE(0.05,E20,5) -> 2.1160485 | F21: =CONFIDENCE(0.05,F20,5) -> 2.5367273 | G21: =CONFIDENCE(0.05,G20,5) -> 3.9839389 | H21: =CONFIDENCE(0.05,H20,5) -> 4.636711 | I21: =CONFIDENCE(0.05,I20,5) -> 5.34175 | ... L21: =CONFIDENCE(0.05,L20,5) -> 6.7618145
A23: incremental deletions 10%
A24: RUN 1 | B24: 140 | C24: 453 | D24: 952 | E24: 1311 | F24: 2090 | G24: 1903 | H24: 1919 | I24: 3073 | J24: 3495 | K24: 3104 | L24: 2340
A25: RUN 2 | B25: 140 | C25: 468 | D25: 998 | E25: 1482 | F25: 2184 | G25: 2043 | H25: 2121 | I25: 3042 | J25: 3759 | K25: 3370 | L25: 2621
A26: RUN 3 | B26: 156 | C26: 452 | D26: 967 | E26: 1372 | F26: 2168 | G26: 1950 | H26: 1950 | I26: 2855 | J26: 3666 | K26: 3167 | L26: 2403
A27: RUN 4 | B27: 141 | C27: 468 | D27: 936 | E27: 1311 | F27: 2169 | G27: 1934 | H27: 1950 | I27: 2839 | J27: 3448 | K27: 3167 | L27: 2402
A28: RUN 5 | B28: 156 | C28: 453 | D28: 936 | E28: 1295 | F28: 2168 | G28: 1965 | H28: 1965 | I28: 2839 | J28: 3385 | K28: 3136 | L28: 2324
A29: AVG | B29: =(SUM(B24:B28) -MAX(B24:B28) -MIN(B24:B28))/((COUNT(B24:B28)-2)*1000) -> 0.14566667 | C29: =(SUM(C24:C28) -MAX(C24:C28) -MIN(C24:C28))/((COUNT(C24:C28)-2)*1000) -> 0.458 | D29: =(SUM(D24:D28) -MAX(D24:D28) -MIN(D24:D28))/((COUNT(D24:D28)-2)*1000) -> 0.95166667 | E29: =(SUM(E24:E28) -MAX(E24:E28) -MIN(E24:E28))/((COUNT(E24:E28)-2)*1000) -> 1.3313333 | F29: =(SUM(F24:F28) -MAX(F24:F28) -MIN(F24:F28))/((COUNT(F24:F28)-2)*1000) -> 2.1683333 | G29: =(SUM(G24:G28) -MAX(G24:G28) -MIN(G24:G28))/((COUNT(G24:G28)-2)*1000) -> 1.9496667 | H29: =(SUM(H24:H28) -MAX(H24:H28) -MIN(H24:H28))/((COUNT(H24:H28)-2)*1000) -> 1.955 | I29: =(SUM(I24:I28) -MAX(I24:I28) -MIN(I24:I28))/((COUNT(I24:I28)-2)*1000) -> 2.912 | ... L29: =(SUM(L24:L28) -MAX(L24:L28) -MIN(L24:L28))/((COUNT(L24:L28)-2)*1000) -> 2.3816667 | M29: sec
A30: STDEV | B30: =STDEV(B24:B28)/1000 -> 0.0085906926 | C30: =STDEV(C24:C28)/1000 -> 0.0084083292 | D30: =STDEV(D24:D28)/1000 -> 0.025907528 | E30: =STDEV(E24:E28)/1000 -> 0.077276775 | F30: =STDEV(F24:F28)/1000 -> 0.037405882 | G30: =STDEV(G24:G28)/1000 -> 0.052282884 | H30: =STDEV(H24:H28)/1000 -> 0.080034368 | I30: =STDEV(I24:I28)/1000 -> 0.11745127 | ... L30: =STDEV(L24:L28)/1000 -> 0.11896428
A31: CONFIDENCE | B31: =CONFIDENCE(0.05,B30,5) -> 0.0075299357 | C31: =CONFIDENCE(0.05,C30,5) -> 0.0073700901 | D31: =CONFIDENCE(0.05,D30,5) -> 0.022708532 | E31: =CONFIDENCE(0.05,E30,5) -> 0.067734835 | F31: =CONFIDENCE(0.05,F30,5) -> 0.032787099 | G31: =CONFIDENCE(0.05,G30,5) -> 0.045827127 | H31: =CONFIDENCE(0.05,H30,5) -> 0.070151927 | I31: =CONFIDENCE(0.05,I30,5) -> 0.10294868 | ... L31: =CONFIDENCE(0.05,L30,5) -> 0.10427487
A33: incremental deletions 50%
A34: RUN 1 | B34: 281 | C34: 1061 | D34: 2667 | E34: 3557 | F34: 5835 | G34: 4961 | H34: 4025 | I34: 6505 | J34: 8253 | K34: 6365 | L34: 4071
A35: RUN 2 | B35: 296 | C35: 1139 | D35: 2854 | E35: 3572 | F35: 6178 | G35: 5257 | H35: 4243 | I35: 6879 | J35: 9484 | K35: 6896 | L35: 4368
A36: RUN 3 | B36: 312 | C36: 1139 | D36: 2855 | E36: 3510 | F36: 6193 | G36: 5257 | H36: 4259 | I36: 6864 | J36: 9251 | K36: 6755 | L36: 4306
A37: RUN 4 | B37: 312 | C37: 1155 | D37: 2839 | E37: 3463 | F37: 6209 | G37: 5258 | H37: 4243 | I37: 7051 | J37: 8861 | K37: 6786 | L37: 4305
A38: RUN 5 | B38: 312 | C38: 1139 | D38: 2855 | E38: 3463 | F38: 6193 | G38: 5257 | H38: 4259 | I38: 7254 | J38: 8799 | K38: 6755 | L38: 4368
A39: AVG | B39: =(SUM(B34:B38) -MAX(B34:B38) -MIN(B34:B38))/((COUNT(B34:B38)-2)*1000) -> 0.30666667 | C39: =(SUM(C34:C38) -MAX(C34:C38) -MIN(C34:C38))/((COUNT(C34:C38)-2)*1000) -> 1.139 | D39: =(SUM(D34:D38) -MAX(D34:D38) -MIN(D34:D38))/((COUNT(D34:D38)-2)*1000) -> 2.8493333 | E39: =(SUM(E34:E38) -MAX(E34:E38) -MIN(E34:E38))/((COUNT(E34:E38)-2)*1000) -> 3.51 | F39: =(SUM(F34:F38) -MAX(F34:F38) -MIN(F34:F38))/((COUNT(F34:F38)-2)*1000) -> 6.188 | G39: =(SUM(G34:G38) -MAX(G34:G38) -MIN(G34:G38))/((COUNT(G34:G38)-2)*1000) -> 5.257 | H39: =(SUM(H34:H38) -MAX(H34:H38) -MIN(H34:H38))/((COUNT(H34:H38)-2)*1000) -> 4.2483333 | I39: =(SUM(I34:I38) -MAX(I34:I38) -MIN(I34:I38))/((COUNT(I34:I38)-2)*1000) -> 6.9313333 | ... L39: =(SUM(L34:L38) -MAX(L34:L38) -MIN(L34:L38))/((COUNT(L34:L38)-2)*1000) -> 4.3263333 | M39: sec
A40: STDEV | B40: =STDEV(B34:B38)/1000 -> 0.013921207 | C40: =STDEV(C34:C38)/1000 -> 0.037320236 | D40: =STDEV(D34:D38)/1000 -> 0.082456049 | E40: =STDEV(E34:E38)/1000 -> 0.051053893 | F40: =STDEV(F34:F38)/1000 -> 0.16058892 | G40: =STDEV(G34:G38)/1000 -> 0.13248774 | H40: =STDEV(H34:H38)/1000 -> 0.10138639 | I40: =STDEV(I34:I38)/1000 -> 0.27627758 | ... L40: =STDEV(L34:L38)/1000 -> 0.12288735
A41: CONFIDENCE | B41: =CONFIDENCE(0.05,B40,5) -> 0.012202252 | C41: =CONFIDENCE(0.05,C40,5) -> 0.032712028 | D41: =CONFIDENCE(0.05,D40,5) -> 0.072274585 | E41: =CONFIDENCE(0.05,E40,5) -> 0.044749888 | F41: =CONFIDENCE(0.05,F40,5) -> 0.1407598 | G41: =CONFIDENCE(0.05,G40,5) -> 0.11612849 | H41: =CONFIDENCE(0.05,H40,5) -> 0.088867456 | I41: =CONFIDENCE(0.05,I40,5) -> 0.24216352 | ... L41: =CONFIDENCE(0.05,L40,5) -> 0.10771353
A43: incremental insertions 1%
A44: RUN 1 | B44: 266 | C44: 1014 | D44: 2106 | E44: 9079 | F44: 2449 | G44: 6240 | H44: 8517 | I44: 17612 | J44: 43789 | K44: 18127 | L44: 13728
...

Sheet int - 8k
A1: scalabilityInt - tuples/peer: | B1: 8k
A2: #peers | B2: 2 | C2: 4 | D2: 6 | E2: 8 | F2: 10 | G2: 12 | H2: 14 | I2: 16
A3: initial solution
A4: RUN 1 | B4: 1856 | C4: 5943 | D4: 13151 | E4: 24118 | F4: 22776 | G4: 44741 | H4: 57097 | I4: 92493
A5: RUN 2 | B5: 1810 | C5: 5803 | D5: 13323 | E5: 24851 | F5: 23228 | G5: 48017 | H5: 60029 | I5: 97423
A6: RUN 3 | B6: 1794 | C6: 5804 | D6: 13229 | E6: 24649 | F6: 23260 | G6: 48127 | H6: 60356 | I6: 97672
A7: RUN 4 | B7: 1810 | C7: 5928 | D7: 13292 | E7: 24570 | F7: 23291 | G7: 48001 | H7: 60232 | I7: 97189
A8: RUN 5 | B8: 1826 | C8: 5912 | D8: 13385 | E8: 24679 | F8: 23291 | G8: 48049 | H8: 60373 | I8: 95286
A9: AVG | B9: =(SUM(B4:B8) -MAX(B4:B8) -MIN(B4:B8))/((COUNT(B4:B8)-2)*1000) -> 1.8153333 | C9: =(SUM(C4:C8) -MAX(C4:C8) -MIN(C4:C8))/((COUNT(C4:C8)-2)*1000) -> 5.8813333 | D9: =(SUM(D4:D8) -MAX(D4:D8) -MIN(D4:D8))/((COUNT(D4:D8)-2)*1000) -> 13.281333 | E9: =(SUM(E4:E8) -MAX(E4:E8) -MIN(E4:E8))/((COUNT(E4:E8)-2)*1000) -> 24.632667 | F9: =(SUM(F4:F8) -MAX(F4:F8) -MIN(F4:F8))/((COUNT(F4:F8)-2)*1000) -> 23.259667 | G9: =(SUM(G4:G8) -MAX(G4:G8) -MIN(G4:G8))/((COUNT(G4:G8)-2)*1000) -> 48.022333 | H9: =(SUM(H4:H8) -MAX(H4:H8) -MIN(H4:H8))/((COUNT(H4:H8)-2)*1000) -> 60.205667 | I9: =(SUM(I4:I8) -MAX(I4:I8) -MIN(I4:I8))/((COUNT(I4:I8)-2)*1000) -> 96.632667 | J9: sec
A10: STDEV | B10: =STDEV(B4:B8)/1000 -> 0.023477649 | C10: =STDEV(C4:C8)/1000 -> 0.06888759 | D10: =STDEV(D4:D8)/1000 -> 0.089693924 | E10: =STDEV(E4:E8)/1000 -> 0.2744673 | F10: =STDEV(F4:F8)/1000 -> 0.22134746 | G10: =STDEV(G4:G8)/1000 -> 1.4799541 | H10: =STDEV(H4:H8)/1000 -> 1.4156293 | I10: =STDEV(I4:I8)/1000 -> 2.1818733
A11: CONFIDENCE | B11: =CONFIDENCE(0.05,B10,5) -> 0.020578689 | C11: =CONFIDENCE(0.05,C10,5) -> 0.060381525 | D11: =CONFIDENCE(0.05,D10,5) -> 0.078618746 | E11: =CONFIDENCE(0.05,E10,5) -> 0.24057678 | F11: =CONFIDENCE(0.05,F10,5) -> 0.19401604 | G11: =CONFIDENCE(0.05,G10,5) -> 1.2972131 | H11: =CONFIDENCE(0.05,H10,5) -> 1.240831 | I11: =CONFIDENCE(0.05,I10,5) -> 1.9124612
A13: incremental deletions 1%
A14: RUN 1 | B14: 671 | C14: 2262 | D14: 4368 | E14: 6443 | F14: 8252 | G14: 11778 | H14: 12854 | I14: 14383
A15: RUN 2 | B15: 141 | C15: 390 | D15: 702 | E15: 1107 | F15: 1560 | G15: 1591 | H15: 1903 | I15: 2527
A16: RUN 3 | B16: 141 | C16: 390 | D16: 702 | E16: 1061 | F16: 1575 | G16: 1575 | H16: 1919 | I16: 2465
A17: RUN 4 | B17: 140 | C17: 375 | D17: 718 | E17: 999 | F17: 1575 | G17: 1576 | H17: 1887 | I17: 2465
A18: RUN 5 | B18: 140 | C18: 390 | D18: 686 | E18: 999 | F18: 1545 | G18: 1576 | H18: 1919 | I18: 2511
A19: AVG | B19: =(SUM(B14:B18) -MAX(B14:B18) -MIN(B14:B18))/((COUNT(B14:B18)-2)*1000) -> 0.14066667 | C19: =(SUM(C14:C18) -MAX(C14:C18) -MIN(C14:C18))/((COUNT(C14:C18)-2)*1000) -> 0.39 | D19: =(SUM(D14:D18) -MAX(D14:D18) -MIN(D14:D18))/((COUNT(D14:D18)-2)*1000) -> 0.70733333 | E19: =(SUM(E14:E18) -MAX(E14:E18) -MIN(E14:E18))/((COUNT(E14:E18)-2)*1000) -> 1.0556667 | F19: =(SUM(F14:F18) -MAX(F14:F18) -MIN(F14:F18))/((COUNT(F14:F18)-2)*1000) -> 1.57 | G19: =(SUM(G14:G18) -MAX(G14:G18) -MIN(G14:G18))/((COUNT(G14:G18)-2)*1000) -> 1.581 | H19: =(SUM(H14:H18) -MAX(H14:H18) -MIN(H14:H18))/((COUNT(H14:H18)-2)*1000) -> 1.9136667 | I19: =(SUM(I14:I18) -MAX(I14:I18) -MIN(I14:I18))/((COUNT(I14:I18)-2)*1000) -> 2.501 | J19: sec
A20: STDEV | B20: =STDEV(B14:B18)/1000 -> 0.23724734 | C20: =STDEV(C14:C18)/1000 -> 0.83888605 | D20: =STDEV(D14:D18)/1000 -> 1.6395241 | E20: =STDEV(E14:E18)/1000 -> 2.4160528 | F20: =STDEV(F14:F18)/1000 -> 2.9911022 | G20: =STDEV(G14:G18)/1000 -> 4.5609127 | H20: =STDEV(H14:H18)/1000 -> 4.8956652 | I20: =STDEV(I14:I18)/1000 -> 5.3178884
A21: CONFIDENCE | B21: =CONFIDENCE(0.05,B20,5) -> 0.20795264 | C21: =CONFIDENCE(0.05,C20,5) -> 0.73530253 | D21: =CONFIDENCE(0.05,D20,5) -> 1.4370798 | E21: =CONFIDENCE(0.05,E20,5) -> 2.1177248 | F21: =CONFIDENCE(0.05,F20,5) -> 2.6217685 | G21: =CONFIDENCE(0.05,G20,5) -> 3.9977428 | H21: =CONFIDENCE(0.05,H20,5) -> 4.2911609 | I21: =CONFIDENCE(0.05,I20,5) -> 4.6612491
A23: incremental deletions 10%
A24: RUN 1 | B24: 171 | C24: 546 | D24: 1186 | E24: 1591 | F24: 2621 | G24: 2356 | H24: 2637 | I24: 3463
A25: RUN 2 | B25: 171 | C25: 562 | D25: 1450 | E25: 1606 | F25: 2746 | G25: 2558 | H25: 2668 | I25: 3791
A26: RUN 3 | B26: 187 | C26: 562 | D26: 1201 | E26: 1576 | F26: 2762 | G26: 2434 | H26: 2449 | I26: 3588
A27: RUN 4 | B27: 187 | C27: 546 | D27: 1201 | E27: 1560 | F27: 2761 | G27: 2480 | H27: 2528 | I27: 3588
A28: RUN 5 | B28: 172 | C28: 562 | D28: 1217 | E28: 1529 | F28: 2699 | G28: 2387 | H28: 2480 | I28: 3572
A29: AVG | B29: =(SUM(B24:B28) -MAX(B24:B28) -MIN(B24:B28))/((COUNT(B24:B28)-2)*1000) -> 0.17666667 | C29: =(SUM(C24:C28) -MAX(C24:C28) -MIN(C24:C28))/((COUNT(C24:C28)-2)*1000) -> 0.55666667 | D29: =(SUM(D24:D28) -MAX(D24:D28) -MIN(D24:D28))/((COUNT(D24:D28)-2)*1000) -> 1.2063333 | E29: =(SUM(E24:E28) -MAX(E24:E28) -MIN(E24:E28))/((COUNT(E24:E28)-2)*1000) -> 1.5756667 | F29: =(SUM(F24:F28) -MAX(F24:F28) -MIN(F24:F28))/((COUNT(F24:F28)-2)*1000) -> 2.7353333 | G29: =(SUM(G24:G28) -MAX(G24:G28) -MIN(G24:G28))/((COUNT(G24:G28)-2)*1000) -> 2.4336667 | H29: =(SUM(H24:H28) -MAX(H24:H28) -MIN(H24:H28))/((COUNT(H24:H28)-2)*1000) -> 2.5483333 | I29: =(SUM(I24:I28) -MAX(I24:I28) -MIN(I24:I28))/((COUNT(I24:I28)-2)*1000) -> 3.5826667 | J29: sec
A30: STDEV | B30: =STDEV(B24:B28)/1000 -> 0.0085906926 | C30: =STDEV(C24:C28)/1000 -> 0.0087635609 | D30: =STDEV(D24:D28)/1000 -> 0.11178327 | E30: =STDEV(E24:E28)/1000 -> 0.029686697 | F30: =STDEV(F24:F28)/1000 -> 0.059872364 | G30: =STDEV(G24:G28)/1000 -> 0.079655508 | H30: =STDEV(H24:H28)/1000 -> 0.096240844 | I30: =STDEV(I24:I28)/1000 -> 0.11866044
A31: CONFIDENCE | B31: =CONFIDENCE(0.05,B30,5) -> 0.0075299357 | C31: =CONFIDENCE(0.05,C30,5) -> 0.0076814587 | D31: =CONFIDENCE(0.05,D30,5) -> 0.097980558 | E31: =CONFIDENCE(0.05,E30,5) -> 0.026021059 | F31: =CONFIDENCE(0.05,F30,5) -> 0.052479477 | G31: =CONFIDENCE(0.05,G30,5) -> 0.069819848 | H31: =CONFIDENCE(0.05,H30,5) -> 0.084357269 | I31: =CONFIDENCE(0.05,I30,5) -> 0.10400855
A33: incremental deletions 50%
A34: RUN 1 | B34: 390 | C34: 1373 | D34: 3494 | E34: 4103 | F34: 7566 | G34: 6349 | H34: 5367 | I34: 8330
A35: RUN 2 | B35: 406 | C35: 1498 | D35: 3994 | E35: 4383 | F35: 7987 | G35: 6801 | H35: 6459 | I35: 10046
A36: RUN 3 | B36: 405 | C36: 1513 | D36: 3744 | E36: 4415 | F36: 7972 | G36: 6770 | H36: 5990 | I36: 9750
A37: RUN 4 | B37: 406 | C37: 1498 | D37: 3728 | E37: 4383 | F37: 7972 | G37: 6755 | H37: 5709 | I37: 8986
A38: RUN 5 | B38: 406 | C38: 1498 | D38: 3728 | E38: 4384 | F38: 8003 | G38: 6739 | H38: 5757 | I38: 9594
A39: AVG | B39: =(SUM(B34:B38) -MAX(B34:B38) -MIN(B34:B38))/((COUNT(B34:B38)-2)*1000) -> 0.40566667 | C39: =(SUM(C34:C38) -MAX(C34:C38) -MIN(C34:C38))/((COUNT(C34:C38)-2)*1000) -> 1.498 | D39: =(SUM(D34:D38) -MAX(D34:D38) -MIN(D34:D38))/((COUNT(D34:D38)-2)*1000) -> 3.7333333 | E39: =(SUM(E34:E38) -MAX(E34:E38) -MIN(E34:E38))/((COUNT(E34:E38)-2)*1000) -> 4.3833333 | F39: =(SUM(F34:F38) -MAX(F34:F38) -MIN(F34:F38))/((COUNT(F34:F38)-2)*1000) -> 7.977 | G39: =(SUM(G34:G38) -MAX(G34:G38) -MIN(G34:G38))/((COUNT(G34:G38)-2)*1000) -> 6.7546667 | H39: =(SUM(H34:H38) -MAX(H34:H38) -MIN(H34:H38))/((COUNT(H34:H38)-2)*1000) -> 5.8186667 | I39: =(SUM(I34:I38) -MAX(I34:I38) -MIN(I34:I38))/((COUNT(I34:I38)-2)*1000) -> 9.4433333 | J39: sec
A40: STDEV | B40: =STDEV(B34:B38)/1000 -> 0.0070569115 | C40: =STDEV(C34:C38)/1000 -> 0.057943938 | D40: =STDEV(D34:D38)/1000 -> 0.17699379 | E40: =STDEV(E34:E38)/1000 -> 0.12963719 | F40: =STDEV(F34:F38)/1000 -> 0.18715101 | G40: =STDEV(G34:G38)/1000 -> 0.18799521 | H40: =STDEV(H34:H38)/1000 -> 0.40376206 | I40: =STDEV(I34:I38)/1000 -> 0.68491985
A41: CONFIDENCE | B41: =CONFIDENCE(0.05,B40,5) -> 0.006185542 | C41: =CONFIDENCE(0.05,C40,5) -> 0.050789168 | D41: =CONFIDENCE(0.05,D40,5) -> 0.15513904 | E41: =CONFIDENCE(0.05,E40,5) -> 0.11362992 | F41: =CONFIDENCE(0.05,F40,5) -> 0.16404208 | G41: =CONFIDENCE(0.05,G40,5) -> 0.16478204 | H41: =CONFIDENCE(0.05,H40,5) -> 0.35390655 | I41: =CONFIDENCE(0.05,I40,5) -> 0.60034769
A43: incremental insertions 1%
A44: RUN 1 | B44: 296 | C44: 1341 | D44: 3213 | E44: 4540 | F44: 3073 | G44: 10749 | H44: 32948 | I44: 22948
...

Sheet int - 10k
A1: scalabilityInt - tuples/peer: | B1: 10k
A2: #peers | B2: 2 | C2: 4 | D2: 6 | E2: 8 | F2: 10 | G2: 12 | H2: 14
A3: initial solution
A4: RUN 1 | B4: 2231 | C4: 7098 | D4: 15241 | E4: 28392 | F4: 27082 | G4: 57518 | H4: 70965
A5: RUN 2 | B5: 2231 | C5: 7301 | D5: 15927 | E5: 29921 | F5: 28407 | G5: 60762 | H5: 80934
A6: RUN 3 | B6: 2246 | C6: 7269 | D6: 15897 | E6: 29968 | F6: 28470 | G6: 60825 | H6: 83273
A7: RUN 4 | B7: 2262 | C7: 7285 | D7: 15897 | E7: 29859 | F7: 28485 | G7: 60903 | H7: 80871
A8: RUN 5 | B8: 2247 | C8: 7270 | D8: 15912 | E8: 29984 | F8: 28455 | G8: 60934 | H8: 80091
A9: AVG | B9: =(SUM(B4:B8) -MAX(B4:B8) -MIN(B4:B8))/((COUNT(B4:B8)-2)*1000) -> 2.2413333 | C9: =(SUM(C4:C8) -MAX(C4:C8) -MIN(C4:C8))/((COUNT(C4:C8)-2)*1000) -> 7.2746667 | D9: =(SUM(D4:D8) -MAX(D4:D8) -MIN(D4:D8))/((COUNT(D4:D8)-2)*1000) -> 15.902 | E9: =(SUM(E4:E8) -MAX(E4:E8) -MIN(E4:E8))/((COUNT(E4:E8)-2)*1000) -> 29.916 | F9: =(SUM(F4:F8) -MAX(F4:F8) -MIN(F4:F8))/((COUNT(F4:F8)-2)*1000) -> 28.444 | G9: =(SUM(G4:G8) -MAX(G4:G8) -MIN(G4:G8))/((COUNT(G4:G8)-2)*1000) -> 60.83 | H9: =(SUM(H4:H8) -MAX(H4:H8) -MIN(H4:H8))/((COUNT(H4:H8)-2)*1000) -> 80.632 | I9: sec
A10: STDEV | B10: =STDEV(B4:B8)/1000 -> 0.012973049 | C10: =STDEV(C4:C8)/1000 -> 0.082983733 | D10: =STDEV(D4:D8)/1000 -> 0.29866235 | E10: =STDEV(E4:E8)/1000 -> 0.69086735 | F10: =STDEV(F4:F8)/1000 -> 0.61438644 | G10: =STDEV(G4:G8)/1000 -> 1.494313 | H10: =STDEV(H4:H8)/1000 -> 4.7695346
A11: CONFIDENCE | B11: =CONFIDENCE(0.05,B10,5) -> 0.01137117 | C11: =CONFIDENCE(0.05,C10,5) -> 0.072737113 | D11: =CONFIDENCE(0.05,D10,5) -> 0.26178428 | E11: =CONFIDENCE(0.05,E10,5) -> 0.60556081 | F11: =CONFIDENCE(0.05,F10,5) -> 0.53852356 | G11: =CONFIDENCE(0.05,G10,5) -> 1.309799 | H11: =CONFIDENCE(0.05,H10,5) -> 4.1806046
A13: incremental deletions 1%
A14: RUN 1 | B14: 687 | C14: 2153 | D14: 4212 | E14: 6412 | F14: 8440 | G14: 11825 | H14: 13229
A15: RUN 2 | B15: 156 | C15: 390 | D15: 749 | E15: 1029 | F15: 1669 | G15: 1747 | H15: 2138
A16: RUN 3 | B16: 156 | C16: 390 | D16: 733 | E16: 1014 | F16: 1638 | G16: 1669 | H16: 2028
A17: RUN 4 | B17: 156 | C17: 390 | D17: 749 | E17: 1029 | F17: 1654 | G17: 1669 | H17: 2028
A18: RUN 5 | B18: 156 | C18: 390 | D18: 733 | E18: 1014 | F18: 1622 | G18: 1685 | H18: 2012
A19: AVG | B19: =(SUM(B14:B18) -MAX(B14:B18) -MIN(B14:B18))/((COUNT(B14:B18)-2)*1000) -> 0.156 | C19: =(SUM(C14:C18) -MAX(C14:C18) -MIN(C14:C18))/((COUNT(C14:C18)-2)*1000) -> 0.39 | D19: =(SUM(D14:D18) -MAX(D14:D18) -MIN(D14:D18))/((COUNT(D14:D18)-2)*1000) -> 0.74366667 | E19: =(SUM(E14:E18) -MAX(E14:E18) -MIN(E14:E18))/((COUNT(E14:E18)-2)*1000) -> 1.024 | F19: =(SUM(F14:F18) -MAX(F14:F18) -MIN(F14:F18))/((COUNT(F14:F18)-2)*1000) -> 1.6536667 | G19: =(SUM(G14:G18) -MAX(G14:G18) -MIN(G14:G18))/((COUNT(G14:G18)-2)*1000) -> 1.7003333 | H19: =(SUM(H14:H18) -MAX(H14:H18) -MIN(H14:H18))/((COUNT(H14:H18)-2)*1000) -> 2.0646667 | I19: sec
A20: STDEV | B20: =STDEV(B14:B18)/1000 -> 0.23747042 | C20: =STDEV(C14:C18)/1000 -> 0.78843757 | D20: =STDEV(D14:D18)/1000 -> 1.552299 | E20: =STDEV(E14:E18)/1000 -> 2.4107166 | F20: =STDEV(F14:F18)/1000 -> 3.0385317 | G20: =STDEV(G14:G18)/1000 -> 4.5315057 | H20: =STDEV(H14:H18)/1000 -> 4.9989837
A21: CONFIDENCE | B21: =CONFIDENCE(0.05,B20,5) -> 0.20814818 | C21: =CONFIDENCE(0.05,C20,5) -> 0.6910833 | D21: =CONFIDENCE(0.05,D20,5) -> 1.3606251 | E21: =CONFIDENCE(0.05,E20,5) -> 2.1130474 | F21: =CONFIDENCE(0.05,F20,5) -> 2.6633415 | G21: =CONFIDENCE(0.05,G20,5) -> 3.9719669 | H21: =CONFIDENCE(0.05,H20,5) -> 4.3817219
A23: incremental deletions 10%
A24: RUN 1 | B24: 187 | C24: 562 | D24: 1311 | E24: 1653 | F24: 3027 | G24: 2823 | H24: 2745
A25: RUN 2 | B25: 187 | C25: 593 | D25: 1388 | E25: 1747 | F25: 3213 | G25: 3042 | H25: 3026
A26: RUN 3 | B26: 187 | C26: 609 | D26: 1388 | E26: 1747 | F26: 3151 | G26: 2824 | H26: 2808
A27: RUN 4 | B27: 203 | C27: 608 | D27: 1389 | E27: 1716 | F27: 3151 | G27: 2761 | H27: 2886
A28: RUN 5 | B28: 203 | C28: 608 | D28: 1388 | E28: 1732 | F28: 3135 | G28: 2777 | H28: 3042
A29: AVG | B29: =(SUM(B24:B28) -MAX(B24:B28) -MIN(B24:B28))/((COUNT(B24:B28)-2)*1000) -> 0.19233333 | C29: =(SUM(C24:C28) -MAX(C24:C28) -MIN(C24:C28))/((COUNT(C24:C28)-2)*1000) -> 0.603 | D29: =(SUM(D24:D28) -MAX(D24:D28) -MIN(D24:D28))/((COUNT(D24:D28)-2)*1000) -> 1.388 | E29: =(SUM(E24:E28) -MAX(E24:E28) -MIN(E24:E28))/((COUNT(E24:E28)-2)*1000) -> 1.7316667 | F29: =(SUM(F24:F28) -MAX(F24:F28) -MIN(F24:F28))/((COUNT(F24:F28)-2)*1000) -> 3.1456667 | G29: =(SUM(G24:G28) -MAX(G24:G28) -MIN(G24:G28))/((COUNT(G24:G28)-2)*1000) -> 2.808 | H29: =(SUM(H24:H28) -MAX(H24:H28) -MIN(H24:H28))/((COUNT(H24:H28)-2)*1000) -> 2.9066667 | I29: sec
A30: STDEV | B30: =STDEV(B24:B28)/1000 -> 0.0087635609 | C30: =STDEV(C24:C28)/1000 -> 0.020137031 | D30: =STDEV(D24:D28)/1000 -> 0.034549964 | E30: =STDEV(E24:E28)/1000 -> 0.03905765 | F30: =STDEV(F24:F28)/1000 -> 0.067563304 | G30: =STDEV(G24:G28)/1000 -> 0.1133724 | H30: =STDEV(H24:H28)/1000 -> 0.13106792
A31: CONFIDENCE | B31: =CONFIDENCE(0.05,B30,5) -> 0.0076814587 | C31: =CONFIDENCE(0.05,C30,5) -> 0.017650561 | D31: =CONFIDENCE(0.05,D30,5) -> 0.030283822 | E31: =CONFIDENCE(0.05,E30,5) -> 0.03423491 | F31: =CONFIDENCE(0.05,F30,5) -> 0.059220759 | G31: =CONFIDENCE(0.05,G30,5) -> 0.09937346 | H31: =CONFIDENCE(0.05,H30,5) -> 0.11488399
A33: incremental deletions 50%
A34: RUN 1 | B34: 437 | C34: 1622 | D34: 4166 | E34: 4914 | F34: 9079 | G34: 7878 | H34: 6552
A35: RUN 2 | B35: 468 | C35: 1747 | D35: 4804 | E35: 5320 | F35: 9656 | G35: 9063 | H35: 9298
A36: RUN 3 | B36: 484 | C36: 1748 | D36: 4680 | E36: 5288 | F36: 9656 | G36: 8705 | H36: 8393
A37: RUN 4 | B37: 483 | C37: 1748 | D37: 4617 | E37: 5273 | F37: 9688 | G37: 8393 | H37: 7083
A38: RUN 5 | B38: 483 | C38: 1747 | D38: 4586 | E38: 5288 | F38: 9687 | G38: 8704 | H38: 6833
A39: AVG | B39: =(SUM(B34:B38) -MAX(B34:B38) -MIN(B34:B38))/((COUNT(B34:B38)-2)*1000) -> 0.478 | C39: =(SUM(C34:C38) -MAX(C34:C38) -MIN(C34:C38))/((COUNT(C34:C38)-2)*1000) -> 1.7473333 | D39: =(SUM(D34:D38) -MAX(D34:D38) -MIN(D34:D38))/((COUNT(D34:D38)-2)*1000) -> 4.6276667 | E39: =(SUM(E34:E38) -MAX(E34:E38) -MIN(E34:E38))/((COUNT(E34:E38)-2)*1000) -> 5.283 | F39: =(SUM(F34:F38) -MAX(F34:F38) -MIN(F34:F38))/((COUNT(F34:F38)-2)*1000) -> 9.6663333 | G39: =(SUM(G34:G38) -MAX(G34:G38) -MIN(G34:G38))/((COUNT(G34:G38)-2)*1000) -> 8.6006667 | H39: =(SUM(H34:H38) -MAX(H34:H38) -MIN(H34:H38))/((COUNT(H34:H38)-2)*1000) -> 7.4363333 | I39: sec
A40: STDEV | B40: =STDEV(B34:B38)/1000 -> 0.020137031 | C40: =STDEV(C34:C38)/1000 -> 0.056127533 | D40: =STDEV(D34:D38)/1000 -> 0.24110952 | E40: =STDEV(E34:E38)/1000 -> 0.17002588 | F40: =STDEV(F34:F38)/1000 -> 0.26555357 | G40: =STDEV(G34:G38)/1000 -> 0.44360264 | H40: =STDEV(H34:H38)/1000 -> 1.1684262
A41: CONFIDENCE | B41: =CONFIDENCE(0.05,B40,5) -> 0.017650561 | C41: =CONFIDENCE(0.05,C40,5) -> 0.049197048 | D41: =CONFIDENCE(0.05,D40,5) -> 0.21133793 | E41: =CONFIDENCE(0.05,E40,5) -> 0.14903152 | F41: =CONFIDENCE(0.05,F40,5) -> 0.23276369 | G41: =CONFIDENCE(0.05,G40,5) -> 0.38882771 | H41: =CONFIDENCE(0.05,H40,5) -> 1.0241519
A43: incremental insertions 1%
A44: RUN 1 | B44: 359 | C44: 1092 | D44: 3182 | E44: 5210 | F44: 14524 | G44: 14711 | H44: 27456
...

Sheet int - 10p
A1: scalabilityInt - vs #peers: | B1: 10
A2: #tuples | B2: ='int - 2k'!B1 -> 2k | C2: ='int - 4k'!B1 -> 4k | D2: ='int - 6k'!B1 -> 6k | E2: ='int - 8k'!B1 -> 8k | F2: ='int - 10k'!B1 -> 10k
A3: initial solution
A4: RUN 1 | B4: ='int - 2k'!B4:B11 -> 8049 | C4: ='int - 4k'!C4:C11 -> 12963 | D4: ='int - 6k'!F4:F11 -> 17441 | E4: ='int - 8k'!F4:F11 -> 22776 | F4: ='int - 10k'!F4:F11 -> 27082
A5: RUN 2 | B5: ='int - 2k'!B5:B12 -> 5959 | C5: ='int - 4k'!C5:C12 -> 11732 | D5: ='int - 6k'!F5:F12 -> 17332 | E5: ='int - 8k'!F5:F12 -> 23228 | F5: ='int - 10k'!F5:F12 -> 28407
A6: RUN 3 | B6: ='int - 2k'!B6:B13 -> 5928 | C6: ='int - 4k'!C6:C13 -> 11731 | D6: ='int - 6k'!F6:F13 -> 17269 | E6: ='int - 8k'!F6:F13 -> 23260 | F6: ='int - 10k'!F6:F13 -> 28470
A7: RUN 4 | B7: ='int - 2k'!B7:B14 -> 5959 | C7: ='int - 4k'!C7:C14 -> 11779 | D7: ='int - 6k'!F7:F14 -> 17285 | E7: ='int - 8k'!F7:F14 -> 23291 | F7: ='int - 10k'!F7:F14 -> 28485
A8: RUN 5 | B8: ='int - 2k'!B8:B15 -> 5975 | C8: ='int - 4k'!C8:C15 -> 11762 | D8: ='int - 6k'!F8:F15 -> 17300 | E8: ='int - 8k'!F8:F15 -> 23291 | F8: ='int - 10k'!F8:F15 -> 28455
A9: AVG | B9: ='int - 2k'!B9:B16 -> 5.9643333 | C9: ='int - 4k'!C9:C16 -> 11.757667 | D9: ='int - 6k'!F9:F16 -> 17.305667 | E9: ='int - 8k'!F9:F16 -> 23.259667 | F9: ='int - 10k'!F9:F16 -> 28.444 | G9: sec
A10: STDEV | B10: ='int - 2k'!B10:B17 -> 0.93650841 | C10: ='int - 4k'!C10:C17 -> 0.54240695 | D10: ='int - 6k'!F10:F17 -> 0.068675323 | E10: ='int - 8k'!F10:F17 -> 0.22134746 | F10: ='int - 10k'!F10:F17 -> 0.61438644
A11: CONFIDENCE | B11: ='int - 2k'!B11:B18 -> 0.82087073 | C11: ='int - 4k'!C11:C18 -> 0.47543192 | D11: ='int - 6k'!F11:F18 -> 0.060195469 | E11: ='int - 8k'!F11:F18 -> 0.19401604 | F11: ='int - 10k'!F11:F18 -> 0.53852356
A13: incremental deletions 1%
A14: RUN 1 | B14: ='int - 2k'!B14:B21 -> 7691 | C14: ='int - 4k'!C14:C21 -> 7395 | D14: ='int - 6k'!F14:F21 -> 7754 | E14: ='int - 8k'!F14:F21 -> 8252 | F14: ='int - 10k'!F14:F21 -> 8440
A15: RUN 2 | B15: ='int - 2k'!B15:B22 -> 858 | C15: ='int - 4k'!C15:C22 -> 1030 | D15: ='int - 6k'!F15:F22 -> 1279 | E15: ='int - 8k'!F15:F22 -> 1560 | F15: ='int - 10k'!F15:F22 -> 1669
A16: RUN 3 | B16: ='int - 2k'!B16:B23 -> 874 | C16: ='int - 4k'!C16:C23 -> 1076 | D16: ='int - 6k'!F16:F23 -> 1279 | E16: ='int - 8k'!F16:F23 -> 1575 | F16: ='int - 10k'!F16:F23 -> 1638
A17: RUN 4 | B17: ='int - 2k'!B17:B24 -> 843 | C17: ='int - 4k'!C17:C24 -> 1092 | D17: ='int - 6k'!F17:F24 -> 1263 | E17: ='int - 8k'!F17:F24 -> 1575 | F17: ='int - 10k'!F17:F24 -> 1654
A18: RUN 5 | B18: ='int - 2k'!B18:B25 -> 858 | C18: ='int - 4k'!C18:C25 -> 1076 | D18: ='int - 6k'!F18:F25 -> 1310 | E18: ='int - 8k'!F18:F25 -> 1545 | F18: ='int - 10k'!F18:F25 -> 1622
A19: AVG | B19: ='int - 2k'!B19:B26 -> 0.86333333 | C19: ='int - 4k'!C19:C26 -> 1.0813333 | D19: ='int - 6k'!F19:F26 -> 1.2893333 | E19: ='int - 8k'!F19:F26 -> 1.57 | F19: ='int - 10k'!F19:F26 -> 1.6536667 | G19: sec
A20: STDEV | B20: ='int - 2k'!B20:B27 -> 3.0557184 | C20: ='int - 4k'!C20:C27 -> 2.8293917 | D20: ='int - 6k'!F20:F27 -> 2.8940811 | E20: ='int - 8k'!F20:F27 -> 2.9911022 | F20: ='int - 10k'!F20:F27 -> 3.0385317
A21: CONFIDENCE | B21: ='int - 2k'!B21:B28 -> 2.678406 | C21: ='int - 4k'!C21:C28 -> 2.4800256 | D21: ='int - 6k'!F21:F28 -> 2.5367273 | E21: ='int - 8k'!F21:F28 -> 2.6217685 | F21: ='int - 10k'!F21:F28 -> 2.6633415
A23: incremental deletions 10%
A24: RUN 1 | B24: ='int - 2k'!B24:B31 -> 1202 | C24: ='int - 4k'!C24:C31 -> 1607 | D24: ='int - 6k'!F24:F31 -> 2090 | E24: ='int - 8k'!F24:F31 -> 2621 | F24: ='int - 10k'!F24:F31 -> 3027
A25: RUN 2 | B25: ='int - 2k'!B25:B32 -> 1155 | C25: ='int - 4k'!C25:C32 -> 1685 | D25: ='int - 6k'!F25:F32 -> 2184 | E25: ='int - 8k'!F25:F32 -> 2746 | F25: ='int - 10k'!F25:F32 -> 3213
A26: RUN 3 | B26: ='int - 2k'!B26:B33 -> 1155 | C26: ='int - 4k'!C26:C33 -> 1716 | D26: ='int - 6k'!F26:F33 -> 2168 | E26: ='int - 8k'!F26:F33 -> 2762 | F26: ='int - 10k'!F26:F33 -> 3151
A27: RUN 4 | B27: ='int - 2k'!B27:B34 -> 1154 | C27: ='int - 4k'!C27:C34 -> 1669 | D27: ='int - 6k'!F27:F34 -> 2169 | E27: ='int - 8k'!F27:F34 -> 2761 | F27: ='int - 10k'!F27:F34 -> 3151
A28: RUN 5 | B28: ='int - 2k'!B28:B35 -> 1139 | C28: ='int - 4k'!C28:C35 -> 1685 | D28: ='int - 6k'!F28:F35 -> 2168 | E28: ='int - 8k'!F28:F35 -> 2699 | F28: ='int - 10k'!F28:F35 -> 3135
A29: AVG | B29: ='int - 2k'!B29:B36 -> 1.1546667 | C29: ='int - 4k'!C29:C36 -> 1.6796667 | D29: ='int - 6k'!F29:F36 -> 2.1683333 | E29: ='int - 8k'!F29:F36 -> 2.7353333 | F29: ='int - 10k'!F29:F36 -> 3.1456667 | G29: sec
A30: STDEV | B30: ='int - 2k'!B30:B37 -> 0.023906066 | C30: ='int - 4k'!C30:C37 -> 0.040333609 | D30: ='int - 6k'!F30:F37 -> 0.037405882 | E30: ='int - 8k'!F30:F37 -> 0.059872364 | F30: ='int - 10k'!F30:F37 -> 0.067563304
A31: CONFIDENCE | B31: ='int - 2k'!B31:B38 -> 0.020954206 | C31: ='int - 4k'!C31:C38 -> 0.035353317 | D31: ='int - 6k'!F31:F38 -> 0.032787099 | E31: ='int - 8k'!F31:F38 -> 0.052479477 | F31: ='int - 10k'!F31:F38 -> 0.059220759
A33: incremental deletions 50%
A34: RUN 1 | B34: ='int - 2k'!B34:B41 -> 2278 | C34: ='int - 4k'!C34:C41 -> 4087 | D34: ='int - 6k'!F34:F41 -> 5835 | E34: ='int - 8k'!F34:F41 -> 7566 | F34: ='int - 10k'!F34:F41 -> 9079
A35: RUN 2 | B35: ='int - 2k'!B35:B42 -> 2402 | C35: ='int - 4k'!C35:C42 -> 4321 | D35: ='int - 6k'!F35:F42 -> 6178 | E35: ='int - 8k'!F35:F42 -> 7987 | F35: ='int - 10k'!F35:F42 -> 9656
A36: RUN 3 | B36: ='int - 2k'!B36:B43 -> 2403 | C36: ='int - 4k'!C36:C43 -> 4321 | D36: ='int - 6k'!F36:F43 -> 6193 | E36: ='int - 8k'!F36:F43 -> 7972 | F36: ='int - 10k'!F36:F43 -> 9656
A37: RUN 4 | B37: ='int - 2k'!B37:B44 -> 2402 | C37: ='int - 4k'!C37:C44 -> 4322 | D37: ='int - 6k'!F37:F44 -> 6209 | E37: ='int - 8k'!F37:F44 -> 7972 | F37: ='int - 10k'!F37:F44 -> 9688
A38: RUN 5 | B38: ='int - 2k'!B38:B45 -> 2387 | C38: ='int - 4k'!C38:C45 -> 4306 | D38: ='int - 6k'!F38:F45 -> 6193 | E38: ='int - 8k'!F38:F45 -> 8003 | F38: ='int - 10k'!F38:F45 -> 9687
A39: AVG | B39: ='int - 2k'!B39:B46 -> 2.397 | C39: ='int - 4k'!C39:C46 -> 4.316 | D39: ='int - 6k'!F39:F46 -> 6.188 | E39: ='int - 8k'!F39:F46 -> 7.977 | F39: ='int - 10k'!F39:F46 -> 9.6663333 | G39: sec
A40: STDEV | B40: ='int - 2k'!B40:B47 -> 0.05429825 | C40: ='int - 4k'!C40:C47 -> 0.10329714 | D40: ='int - 6k'!F40:F47 -> 0.16058892 | E40: ='int - 8k'!F40:F47 -> 0.18715101 | F40: ='int - 10k'!F40:F47 -> 0.26555357
A41: CONFIDENCE | B41: ='int - 2k'!B41:B48 -> 0.04759364 | C41: ='int - 4k'!C41:C48 -> 0.090542275 | D41: ='int - 6k'!F41:F48 -> 0.1407598 | E41: ='int - 8k'!F41:F48 -> 0.16404208 | F41: ='int - 10k'!F41:F48 -> 0.23276369
A43: incremental insertions 1%
A44: RUN 1 | B44: ='int - 2k'!B44:B51 -> 1217 | C44: ='int - 4k'!C44:C51 -> 1809 | D44: ='int - 6k'!F44:F51 -> 2449 | E44: ='int - 8k'!F44:F51 -> 3073 | F44: ='int - 10k'!F44:F51 -> 14524
...

Sheet str - 2k
A1: scalabilityStr - tuples/peer: | B1: 2k
A2: #peers | B2: 10 | C2: 20 | D2: 30 | E2: 40 | F2: 50
A3: initial solution
A4: RUN 1 | B4: 26395 | C4: 102884 | D4: 238202 | E4: 450797 | F4: 537315
A5: RUN 2 | B5: 42416 | C5: 245752 | D5: 448204 | E5: 1058308 | F5: 1021415
A6: RUN 3 | B6: 44615 | C6: 239897 | D6: 461433 | E6: 1045364 | F6: 1155266
A7: RUN 4 | B7: 42430 | C7: 237448 | D7: 452324 | E7: 1051755 | F7: 1150273
A8: RUN 5 | B8: 33214 | C8: 235811 | D8: 457690 | E8: 1053058 | F8: 1168539
A9: AVG | B9: =(SUM(B4:B8) -MAX(B4:B8) -MIN(B4:B8))/((COUNT(B4:B8)-2)*1000) -> 39.353333 | C9: =(SUM(C4:C8) -MAX(C4:C8) -MIN(C4:C8))/((COUNT(C4:C8)-2)*1000) -> 237.71867 | D9: =(SUM(D4:D8) -MAX(D4:D8) -MIN(D4:D8))/((COUNT(D4:D8)-2)*1000) -> 452.73933 | E9: =(SUM(E4:E8) -MAX(E4:E8) -MIN(E4:E8))/((COUNT(E4:E8)-2)*1000) -> 1050.059 | F9: =(SUM(F4:F8) -MAX(F4:F8) -MIN(F4:F8))/((COUNT(F4:F8)-2)*1000) -> 1108.9847 | G9: sec
A10: STDEV | B10: =STDEV(B4:B8)/1000 -> 7.7506939 | C10: =STDEV(C4:C8)/1000 -> 61.314076 | D10: =STDEV(D4:D8)/1000 -> 97.047379 | E10: =STDEV(E4:E8)/1000 -> 268.95986 | F10: =STDEV(F4:F8)/1000 -> 268.98682
A11: CONFIDENCE | B11: =CONFIDENCE(0.05,B10,5) -> 6.7936579 | C11: =CONFIDENCE(0.05,C10,5) -> 53.74317 | D11: =CONFIDENCE(0.05,D10,5) -> 85.064215 | E11: =CONFIDENCE(0.05,E10,5) -> 235.74938 | F11: =CONFIDENCE(0.05,F10,5) -> 235.77301
A13: incremental deletions 1%
A14: RUN 1 | B14: 12183 | C14: 17922 | D14: 32634 | E14: 44045 | F14: 97372
A15: RUN 2 | B15: 12090 | C15: 18971 | D15: 32509 | E15: 47363 | F15: 86831
A16: RUN 3 | B16: 11935 | C16: 17906 | D16: 30923 | E16: 48373 | F16: 90858
A17: RUN 4 | B17: 11936 | C17: 18284 | D17: 31306 | E17: 48623 | F17: 86457
A18: RUN 5 | B18: 11869 | C18: 18203 | D18: 31434 | E18: 46986 | F18: 86691
A19: AVG | B19: =(SUM(B14:B18) -MAX(B14:B18) -MIN(B14:B18))/((COUNT(B14:B18)-2)*1000) -> 11.987 | C19: =(SUM(C14:C18) -MAX(C14:C18) -MIN(C14:C18))/((COUNT(C14:C18)-2)*1000) -> 18.136333 | D19: =(SUM(D14:D18) -MAX(D14:D18) -MIN(D14:D18))/((COUNT(D14:D18)-2)*1000) -> 31.749667 | E19: =(SUM(E14:E18) -MAX(E14:E18) -MIN(E14:E18))/((COUNT(E14:E18)-2)*1000) -> 47.574 | F19: =(SUM(F14:F18) -MAX(F14:F18) -MIN(F14:F18))/((COUNT(F14:F18)-2)*1000) -> 88.126667 | G19: sec
A20: STDEV | B20: =STDEV(B14:B18)/1000 -> 0.12945772 | C20: =STDEV(C14:C18)/1000 -> 0.43268545 | D20: =STDEV(D14:D18)/1000 -> 0.76449833 | E20: =STDEV(E14:E18)/1000 -> 1.8270761 | F20: =STDEV(F14:F18)/1000 -> 4.6900401
A21: CONFIDENCE | B21: =CONFIDENCE(0.05,B20,5) -> 0.11347261 | C21: =CONFIDENCE(0.05,C20,5) -> 0.37925855 | D21: =CONFIDENCE(0.05,D20,5) -> 0.67010002 | E21: =CONFIDENCE(0.05,E20,5) -> 1.6014734 | F21: =CONFIDENCE(0.05,F20,5) -> 4.1109258
A23: incremental deletions 10%
A24: RUN 1 | B24: 12544 | C24: 19442 | D24: 34855 | E24: 49749 | F24: 97105
A25: RUN 2 | B25: 12357 | C25: 19234 | D25: 32514 | E25: 46117 | F25: 93741
A26: RUN 3 | B26: 12248 | C26: 19457 | D26: 32798 | E26: 46756 | F26: 94054
A27: RUN 4 | B27: 12306 | C27: 19517 | D27: 32883 | E27: 51059 | F27: 93430
A28: RUN 5 | B28: 12263 | C28: 19828 | D28: 35753 | E28: 48489 | F28: 95679
A29: AVG | B29: =(SUM(B24:B28) -MAX(B24:B28) -MIN(B24:B28))/((COUNT(B24:B28)-2)*1000) -> 12.308667 | C29: =(SUM(C24:C28) -MAX(C24:C28) -MIN(C24:C28))/((COUNT(C24:C28)-2)*1000) -> 19.472 | D29: =(SUM(D24:D28) -MAX(D24:D28) -MIN(D24:D28))/((COUNT(D24:D28)-2)*1000) -> 33.512 | E29: =(SUM(E24:E28) -MAX(E24:E28) -MIN(E24:E28))/((COUNT(E24:E28)-2)*1000) -> 48.331333 | F29: =(SUM(F24:F28) -MAX(F24:F28) -MIN(F24:F28))/((COUNT(F24:F28)-2)*1000) -> 94.491333 | G29: sec
A30: STDEV | B30: =STDEV(B24:B28)/1000 -> 0.11978022 | C30: =STDEV(C24:C28)/1000 -> 0.21432755 | D30: =STDEV(D24:D28)/1000 -> 1.4507034 | E30: =STDEV(E24:E28)/1000 -> 2.04982 | F30: =STDEV(F24:F28)/1000 -> 1.5524615
A31: CONFIDENCE | B31: =CONFIDENCE(0.05,B30,5) -> 0.10499006 | C31: =CONFIDENCE(0.05,C30,5) -> 0.18786293 | D31: =CONFIDENCE(0.05,D30,5) -> 1.2715742 | E31: =CONFIDENCE(0.05,E30,5) -> 1.7967134 | F31: =CONFIDENCE(0.05,F30,5) -> 1.3607675
A33: incremental deletions 50%
A34: RUN 1 | B34: 22152 | C34: 24274 | D34: 38034 | E34: 56315 | F34: 115466
A35: RUN 2 | B35: 13869 | C35: 25680 | D35: 40409 | E35: 58316 | F35: 117377
A36: RUN 3 | B36: 13510 | C36: 25023 | D36: 43709 | E36: 60559 | F36: 122368
A37: RUN 4 | B37: 13647 | C37: 25601 | D37: 43401 | E37: 59140 | F37: 118748
A38: RUN 5 | B38: 13508 | C38: 25025 | D38: 41250 | E38: 57160 | F38: 117612
A39: AVG | B39: =(SUM(B34:B38) -MAX(B34:B38) -MIN(B34:B38))/((COUNT(B34:B38)-2)*1000) -> 13.675333 | C39: =(SUM(C34:C38) -MAX(C34:C38) -MIN(C34:C38))/((COUNT(C34:C38)-2)*1000) -> 25.216333 | D39: =(SUM(D34:D38) -MAX(D34:D38) -MIN(D34:D38))/((COUNT(D34:D38)-2)*1000) -> 41.686667 | E39: =(SUM(E34:E38) -MAX(E34:E38) -MIN(E34:E38))/((COUNT(E34:E38)-2)*1000) -> 58.205333 | F39: =(SUM(F34:F38) -MAX(F34:F38) -MIN(F34:F38))/((COUNT(F34:F38)-2)*1000) -> 117.91233 | G39: sec
A40: STDEV | B40: =STDEV(B34:B38)/1000 -> 3.8124309 | C40: =STDEV(C34:C38)/1000 -> 0.56548855 | D40: =STDEV(D34:D38)/1000 -> 2.3271365 | E40: =STDEV(E34:E38)/1000 -> 1.6619824 | F40: =STDEV(F34:F38)/1000 -> 2.5546599
A41: CONFIDENCE | B41: =CONFIDENCE(0.05,B40,5) -> 3.3416817 | C41: =CONFIDENCE(0.05,C40,5) -> 0.49566346 | D41: =CONFIDENCE(0.05,D40,5) -> 2.0397876 | E41: =CONFIDENCE(0.05,E40,5) -> 1.456765 | F41: =CONFIDENCE(0.05,F40,5) -> 2.239217
A43: incremental insertions 1%
A44: RUN 1 | B44: 11979 | C44: 51901 | D44: 95413 | E44: 119685 | F44: 178949
...

Sheet str - 4k
A1: scalabilityStr - tuples/peer: | B1: 4k
A2: #peers | B2: 5 | C2: 10 | D2: 15 | E2: 20 | F2: 25
A3: initial solution
A4: RUN 1 | B4: 13324 | C4: 43120 | D4: 143706 | E4: 268168 | F4: 274983
A5: RUN 2 | B5: 23433 | C5: 98906 | D5: 335277 | E5: 641119 | F5: 507844
A6: RUN 3 | B6: 20809 | C6: 97438 | D6: 330549 | E6: 668993 | F6: 508424
A7: RUN 4 | B7: 19829 | C7: 97189 | D7: 333018 | E7: 653787 | F7: 509060
A8: RUN 5 | B8: 20155 | C8: 97548 | D8: 325793 | E8: 653156 | F8: 516333
A9: AVG | B9: =(SUM(B4:B8) -MAX(B4:B8) -MIN(B4:B8))/((COUNT(B4:B8)-2)*1000) -> 20.264333 | C9: =(SUM(C4:C8) -MAX(C4:C8) -MIN(C4:C8))/((COUNT(C4:C8)-2)*1000) -> 97.391667 | D9: =(SUM(D4:D8) -MAX(D4:D8) -MIN(D4:D8))/((COUNT(D4:D8)-2)*1000) -> 329.78667 | E9: =(SUM(E4:E8) -MAX(E4:E8) -MIN(E4:E8))/((COUNT(E4:E8)-2)*1000) -> 649.354 | F9: =(SUM(F4:F8) -MAX(F4:F8) -MIN(F4:F8))/((COUNT(F4:F8)-2)*1000) -> 508.44267 | G9: sec
A10: STDEV | B10: =STDEV(B4:B8)/1000 -> 3.7370347 | C10: =STDEV(C4:C8)/1000 -> 24.449476 | D10: =STDEV(D4:D8)/1000 -> 83.905537 | E10: =STDEV(E4:E8)/1000 -> 172.95023 | F10: =STDEV(F4:F8)/1000 -> 105.3448
A11: CONFIDENCE | B11: =CONFIDENCE(0.05,B10,5) -> 3.2755951 | C11: =CONFIDENCE(0.05,C10,5) -> 21.430516 | D11: =CONFIDENCE(0.05,D10,5) -> 73.545095 | E11: =CONFIDENCE(0.05,E10,5) -> 151.59478 | F11: =CONFIDENCE(0.05,F10,5) -> 92.337093
A13: incremental deletions 1%
A14: RUN 1 | B14: 1280 | C14: 13007 | D14: 15116 | E14: 19375 | F14: 32698
A15: RUN 2 | B15: 1124 | C15: 12556 | D15: 14585 | E15: 18923 | F15: 32386
A16: RUN 3 | B16: 1123 | C16: 13057 | D16: 14586 | E16: 18923 | F16: 35208
A17: RUN 4 | B17: 1139 | C17: 12729 | D17: 14463 | E17: 19205 | F17: 32524
A18: RUN 5 | B18: 1139 | C18: 12262 | D18: 14437 | E18: 19251 | F18: 33103
A19: AVG | B19: =(SUM(B14:B18) -MAX(B14:B18) -MIN(B14:B18))/((COUNT(B14:B18)-2)*1000) -> 1.134 | C19: =(SUM(C14:C18) -MAX(C14:C18) -MIN(C14:C18))/((COUNT(C14:C18)-2)*1000) -> 12.764 | D19: =(SUM(D14:D18) -MAX(D14:D18) -MIN(D14:D18))/((COUNT(D14:D18)-2)*1000) -> 14.544667 | E19: =(SUM(E14:E18) -MAX(E14:E18) -MIN(E14:E18))/((COUNT(E14:E18)-2)*1000) -> 19.126333 | F19: =(SUM(F14:F18) -MAX(F14:F18) -MIN(F14:F18))/((COUNT(F14:F18)-2)*1000) -> 32.775 | G19: sec
A20: STDEV | B20: =STDEV(B14:B18)/1000 -> 0.066973876 | C20: =STDEV(C14:C18)/1000 -> 0.3288825 | D20: =STDEV(D14:D18)/1000 -> 0.27614362 | E20: =STDEV(E14:E18)/1000 -> 0.20361925 | F20: =STDEV(F14:F18)/1000 -> 1.163157
A21: CONFIDENCE | B21: =CONFIDENCE(0.05,B20,5) -> 0.058704112 | C21: =CONFIDENCE(0.05,C20,5) -> 0.28827293 | D21: =CONFIDENCE(0.05,D20,5) -> 0.24204611 | E21: =CONFIDENCE(0.05,E20,5) -> 0.17847686 | F21: =CONFIDENCE(0.05,F20,5) -> 1.0195333
A23: incremental deletions 10%
A24: RUN 1 | B24: 1234 | C24: 13684 | D24: 16536 | E24: 21839 | F24: 36474
A25: RUN 2 | B25: 1264 | C25: 13887 | D25: 17533 | E25: 22372 | F25: 39387
A26: RUN 3 | B26: 1217 | C26: 13627 | D26: 17359 | E26: 21439 | F26: 36796
A27: RUN 4 | B27: 1155 | C27: 13668 | D27: 17737 | E27: 22935 | F27: 36335
A28: RUN 5 | B28: 1201 | C28: 13680 | D28: 17801 | E28: 21557 | F28: 37194
A29: AVG | B29: =(SUM(B24:B28) -MAX(B24:B28) -MIN(B24:B28))/((COUNT(B24:B28)-2)*1000) -> 1.2173333 | C29: =(SUM(C24:C28) -MAX(C24:C28) -MIN(C24:C28))/((COUNT(C24:C28)-2)*1000) -> 13.677333 | D29: =(SUM(D24:D28) -MAX(D24:D28) -MIN(D24:D28))/((COUNT(D24:D28)-2)*1000) -> 17.543 | E29: =(SUM(E24:E28) -MAX(E24:E28) -MIN(E24:E28))/((COUNT(E24:E28)-2)*1000) -> 21.922667 | F29: =(SUM(F24:F28) -MAX(F24:F28) -MIN(F24:F28))/((COUNT(F24:F28)-2)*1000) -> 36.821333 | G29: sec
A30: STDEV | B30: =STDEV(B24:B28)/1000 -> 0.040493209 | C30: =STDEV(C24:C28)/1000 -> 0.10192497 | D30: =STDEV(D24:D28)/1000 -> 0.50990313 | E30: =STDEV(E24:E28)/1000 -> 0.62158411 | F30: =STDEV(F24:F28)/1000 -> 1.2464553
A31: CONFIDENCE | B31: =CONFIDENCE(0.05,B30,5) -> 0.035493211 | C31: =CONFIDENCE(0.05,C30,5) -> 0.089339536 | D31: =CONFIDENCE(0.05,D30,5) -> 0.44694159 | E31: =CONFIDENCE(0.05,E30,5) -> 0.54483248 | F31: =CONFIDENCE(0.05,F30,5) -> 1.0925461
A33: incremental deletions 50%
A34: RUN 1 | B34: 1811 | C34: 17360 | D34: 21077 | E34: 28408 | F34: 49080
A35: RUN 2 | B35: 2060 | C35: 18721 | D35: 23055 | E35: 34071 | F35: 51576
A36: RUN 3 | B36: 1794 | C36: 19172 | D36: 22822 | E36: 30230 | F36: 53449
A37: RUN 4 | B37: 1779 | C37: 18846 | D37: 22603 | E37: 30794 | F37: 49748
A38: RUN 5 | B38: 1747 | C38: 18679 | D38: 22555 | E38: 29999 | F38: 49500
A39: AVG | B39: =(SUM(B34:B38) -MAX(B34:B38) -MIN(B34:B38))/((COUNT(B34:B38)-2)*1000) -> 1.7946667 | C39: =(SUM(C34:C38) -MAX(C34:C38) -MIN(C34:C38))/((COUNT(C34:C38)-2)*1000) -> 18.748667 | D39: =(SUM(D34:D38) -MAX(D34:D38) -MIN(D34:D38))/((COUNT(D34:D38)-2)*1000) -> 22.66 | E39: =(SUM(E34:E38) -MAX(E34:E38) -MIN(E34:E38))/((COUNT(E34:E38)-2)*1000) -> 30.341 | F39: =(SUM(F34:F38) -MAX(F34:F38) -MIN(F34:F38))/((COUNT(F34:F38)-2)*1000) -> 50.274667 | G39: sec
A40: STDEV | B40: =STDEV(B34:B38)/1000 -> 0.12620499 | C40: =STDEV(C34:C38)/1000 -> 0.69575951 | D40: =STDEV(D34:D38)/1000 -> 0.77784369 | E40: =STDEV(E34:E38)/1000 -> 2.0819487 | F40: =STDEV(F34:F38)/1000 -> 1.8228247
A41: CONFIDENCE | B41: =CONFIDENCE(0.05,B40,5) -> 0.11062152 | C41: =CONFIDENCE(0.05,C40,5) -> 0.6098489 | D41: =CONFIDENCE(0.05,D40,5) -> 0.68179752 | E41: =CONFIDENCE(0.05,E40,5) -> 1.8248749 | F41: =CONFIDENCE(0.05,F40,5) -> 1.5977469
A43: incremental insertions 1%
A44: RUN 1 | B44: 5009 | C44: 15446 | D44: 33555 | E44: 54815 | F44: 61840
...

Sheet str - 6k
A1: scalabilityStr - tuples/peer: | B1: 6k
A2: #peers | B2: 2 | C2: 4 | D2: 6 | E2: 8 | F2: 10 | G2: 12 | H2: 14 | I2: 16
A3: initial solution
